2024-10-22 14:56:18,495 - __main__ - INFO - Fernet успішно ініціалізовано
2024-10-22 14:56:18,495 - __main__ - INFO - База даних успішно ініціалізована
2024-10-22 14:56:18,495 - __main__ - INFO - Starting the bot
2024-10-22 14:56:18,992 - __main__ - INFO - Handlers added, starting polling
2024-10-22 14:56:19,268 - httpx - INFO - HTTP Request: POST https://api.telegram.org/bot7388192040:AAE6ySUHROsj21UOZkSxs4uOmdVnRrKTmC4/getMe "HTTP/1.1 200 OK"
2024-10-22 14:56:19,366 - httpx - INFO - HTTP Request: POST https://api.telegram.org/bot7388192040:AAE6ySUHROsj21UOZkSxs4uOmdVnRrKTmC4/deleteWebhook "HTTP/1.1 200 OK"
2024-10-22 14:56:19,366 - telegram.ext.Application - INFO - Application started
2024-10-22 14:56:27,873 - httpx - INFO - HTTP Request: POST https://api.telegram.org/bot7388192040:AAE6ySUHROsj21UOZkSxs4uOmdVnRrKTmC4/getUpdates "HTTP/1.1 200 OK"
2024-10-22 14:56:27,877 - __main__ - INFO - Команда /start від користувача 867084500
2024-10-22 14:56:27,880 - __main__ - INFO - Знайдено існуючий гаманець для користувача 867084500
2024-10-22 14:56:29,195 - httpx - INFO - HTTP Request: POST https://api.telegram.org/bot7388192040:AAE6ySUHROsj21UOZkSxs4uOmdVnRrKTmC4/sendMessage "HTTP/1.1 200 OK"
2024-10-22 14:56:31,151 - httpx - INFO - HTTP Request: POST https://api.telegram.org/bot7388192040:AAE6ySUHROsj21UOZkSxs4uOmdVnRrKTmC4/getUpdates "HTTP/1.1 200 OK"
2024-10-22 14:56:33,188 - httpx - INFO - HTTP Request: POST https://api.telegram.org/bot7388192040:AAE6ySUHROsj21UOZkSxs4uOmdVnRrKTmC4/sendMessage "HTTP/1.1 200 OK"
2024-10-22 14:56:34,837 - httpx - INFO - HTTP Request: POST https://api.telegram.org/bot7388192040:AAE6ySUHROsj21UOZkSxs4uOmdVnRrKTmC4/getUpdates "HTTP/1.1 200 OK"
2024-10-22 14:56:34,840 - __main__ - INFO - Отримано натискання кнопки від користувача 867084500: Отримати зашифрований ключ
2024-10-22 14:56:34,842 - __main__ - INFO - Знайдено дані гаманця для користувача 867084500
2024-10-22 14:56:34,843 - __main__ - INFO - Відправляємо зашифрований ключ користувачу 867084500
2024-10-22 14:56:35,031 - httpx - INFO - HTTP Request: POST https://api.telegram.org/bot7388192040:AAE6ySUHROsj21UOZkSxs4uOmdVnRrKTmC4/sendMessage "HTTP/1.1 200 OK"
2024-10-22 14:56:35,045 - __main__ - INFO - Відповідь успішно надіслано користувачу 867084500
2024-10-22 14:56:36,997 - httpx - INFO - HTTP Request: POST https://api.telegram.org/bot7388192040:AAE6ySUHROsj21UOZkSxs4uOmdVnRrKTmC4/getUpdates "HTTP/1.1 200 OK"
2024-10-22 14:56:37,001 - __main__ - INFO - Отримано натискання кнопки від користувача 867084500: Отримати розшифрований ключ
2024-10-22 14:56:37,003 - __main__ - INFO - Знайдено дані гаманця для користувача 867084500
2024-10-22 14:56:37,004 - __main__ - INFO - Спроба розшифрування ключа для користувача 867084500
2024-10-22 14:56:37,004 - __main__ - INFO - Починаємо розшифрування приватного ключа
2024-10-22 14:56:37,005 - __main__ - ERROR - Помилка розшифрування: Невірний ключ шифрування або пошкоджені дані
2024-10-22 14:56:37,006 - __main__ - ERROR - Помилка при розшифруванні: Неможливо розшифрувати ключ. Можливо, змінився ключ шифрування або дані пошкоджені., тип помилки: <class 'ValueError'>
2024-10-22 14:56:37,008 - __main__ - ERROR - Помилка при розшифруванні для користувача 867084500: Неможливо розшифрувати ключ. Можливо, змінився ключ шифрування або дані пошкоджені.
2024-10-22 14:56:37,193 - httpx - INFO - HTTP Request: POST https://api.telegram.org/bot7388192040:AAE6ySUHROsj21UOZkSxs4uOmdVnRrKTmC4/sendMessage "HTTP/1.1 200 OK"
2024-10-22 14:56:37,195 - __main__ - INFO - Відповідь успішно надіслано користувачу 867084500
2024-10-22 14:56:47,124 - httpx - INFO - HTTP Request: POST https://api.telegram.org/bot7388192040:AAE6ySUHROsj21UOZkSxs4uOmdVnRrKTmC4/getUpdates "HTTP/1.1 200 OK"
2024-10-22 14:56:57,259 - httpx - INFO - HTTP Request: POST https://api.telegram.org/bot7388192040:AAE6ySUHROsj21UOZkSxs4uOmdVnRrKTmC4/getUpdates "HTTP/1.1 200 OK"
2024-10-22 14:57:07,397 - httpx - INFO - HTTP Request: POST https://api.telegram.org/bot7388192040:AAE6ySUHROsj21UOZkSxs4uOmdVnRrKTmC4/getUpdates "HTTP/1.1 200 OK"
2024-10-22 15:46:03,658 - httpx - INFO - HTTP Request: POST https://api.telegram.org/bot7388192040:AAE6ySUHROsj21UOZkSxs4uOmdVnRrKTmC4/getUpdates "HTTP/1.1 200 OK"
2024-10-22 15:46:03,689 - telegram.ext.Application - ERROR - No error handlers are registered, logging exception.
Traceback (most recent call last):
  File "C:\Users\Стас\AppData\Local\Programs\Python\Python312\Lib\site-packages\httpx\_transports\default.py", line 72, in map_httpcore_exceptions
    yield
  File "C:\Users\Стас\AppData\Local\Programs\Python\Python312\Lib\site-packages\httpx\_transports\default.py", line 377, in handle_async_request
    resp = await self._pool.handle_async_request(req)
           ^^^^^^^^^^^^^^^^^^^^^^^^^^^^^^^^^^^^^^^^^^
  File "C:\Users\Стас\AppData\Local\Programs\Python\Python312\Lib\site-packages\httpcore\_async\connection_pool.py", line 216, in handle_async_request
    raise exc from None
  File "C:\Users\Стас\AppData\Local\Programs\Python\Python312\Lib\site-packages\httpcore\_async\connection_pool.py", line 196, in handle_async_request
    response = await connection.handle_async_request(
               ^^^^^^^^^^^^^^^^^^^^^^^^^^^^^^^^^^^^^^
  File "C:\Users\Стас\AppData\Local\Programs\Python\Python312\Lib\site-packages\httpcore\_async\connection.py", line 101, in handle_async_request
    return await self._connection.handle_async_request(request)
           ^^^^^^^^^^^^^^^^^^^^^^^^^^^^^^^^^^^^^^^^^^^^^^^^^^^^
  File "C:\Users\Стас\AppData\Local\Programs\Python\Python312\Lib\site-packages\httpcore\_async\http11.py", line 143, in handle_async_request
    raise exc
  File "C:\Users\Стас\AppData\Local\Programs\Python\Python312\Lib\site-packages\httpcore\_async\http11.py", line 113, in handle_async_request
    ) = await self._receive_response_headers(**kwargs)
        ^^^^^^^^^^^^^^^^^^^^^^^^^^^^^^^^^^^^^^^^^^^^^^
  File "C:\Users\Стас\AppData\Local\Programs\Python\Python312\Lib\site-packages\httpcore\_async\http11.py", line 186, in _receive_response_headers
    event = await self._receive_event(timeout=timeout)
            ^^^^^^^^^^^^^^^^^^^^^^^^^^^^^^^^^^^^^^^^^^
  File "C:\Users\Стас\AppData\Local\Programs\Python\Python312\Lib\site-packages\httpcore\_async\http11.py", line 224, in _receive_event
    data = await self._network_stream.read(
           ^^^^^^^^^^^^^^^^^^^^^^^^^^^^^^^^
  File "C:\Users\Стас\AppData\Local\Programs\Python\Python312\Lib\site-packages\httpcore\_backends\anyio.py", line 32, in read
    with map_exceptions(exc_map):
  File "C:\Users\Стас\AppData\Local\Programs\Python\Python312\Lib\contextlib.py", line 158, in __exit__
    self.gen.throw(value)
  File "C:\Users\Стас\AppData\Local\Programs\Python\Python312\Lib\site-packages\httpcore\_exceptions.py", line 14, in map_exceptions
    raise to_exc(exc) from exc
httpcore.ReadError

The above exception was the direct cause of the following exception:

Traceback (most recent call last):
  File "C:\Users\Стас\AppData\Local\Programs\Python\Python312\Lib\site-packages\telegram\request\_httpxrequest.py", line 292, in do_request
    res = await self._client.request(
          ^^^^^^^^^^^^^^^^^^^^^^^^^^^
  File "C:\Users\Стас\AppData\Local\Programs\Python\Python312\Lib\site-packages\httpx\_client.py", line 1585, in request
    return await self.send(request, auth=auth, follow_redirects=follow_redirects)
           ^^^^^^^^^^^^^^^^^^^^^^^^^^^^^^^^^^^^^^^^^^^^^^^^^^^^^^^^^^^^^^^^^^^^^^
  File "C:\Users\Стас\AppData\Local\Programs\Python\Python312\Lib\site-packages\httpx\_client.py", line 1674, in send
    response = await self._send_handling_auth(
               ^^^^^^^^^^^^^^^^^^^^^^^^^^^^^^^
  File "C:\Users\Стас\AppData\Local\Programs\Python\Python312\Lib\site-packages\httpx\_client.py", line 1702, in _send_handling_auth
    response = await self._send_handling_redirects(
               ^^^^^^^^^^^^^^^^^^^^^^^^^^^^^^^^^^^^
  File "C:\Users\Стас\AppData\Local\Programs\Python\Python312\Lib\site-packages\httpx\_client.py", line 1739, in _send_handling_redirects
    response = await self._send_single_request(request)
               ^^^^^^^^^^^^^^^^^^^^^^^^^^^^^^^^^^^^^^^^
  File "C:\Users\Стас\AppData\Local\Programs\Python\Python312\Lib\site-packages\httpx\_client.py", line 1776, in _send_single_request
    response = await transport.handle_async_request(request)
               ^^^^^^^^^^^^^^^^^^^^^^^^^^^^^^^^^^^^^^^^^^^^^
  File "C:\Users\Стас\AppData\Local\Programs\Python\Python312\Lib\site-packages\httpx\_transports\default.py", line 376, in handle_async_request
    with map_httpcore_exceptions():
  File "C:\Users\Стас\AppData\Local\Programs\Python\Python312\Lib\contextlib.py", line 158, in __exit__
    self.gen.throw(value)
  File "C:\Users\Стас\AppData\Local\Programs\Python\Python312\Lib\site-packages\httpx\_transports\default.py", line 89, in map_httpcore_exceptions
    raise mapped_exc(message) from exc
httpx.ReadError

The above exception was the direct cause of the following exception:

Traceback (most recent call last):
  File "C:\Users\Стас\AppData\Local\Programs\Python\Python312\Lib\site-packages\telegram\ext\_updater.py", line 753, in _network_loop_retry
    if not await do_action():
           ^^^^^^^^^^^^^^^^^
  File "C:\Users\Стас\AppData\Local\Programs\Python\Python312\Lib\site-packages\telegram\ext\_updater.py", line 747, in do_action
    return action_cb_task.result()
           ^^^^^^^^^^^^^^^^^^^^^^^
  File "C:\Users\Стас\AppData\Local\Programs\Python\Python312\Lib\site-packages\telegram\ext\_updater.py", line 377, in polling_action_cb
    updates = await self.bot.get_updates(
              ^^^^^^^^^^^^^^^^^^^^^^^^^^^
  File "C:\Users\Стас\AppData\Local\Programs\Python\Python312\Lib\site-packages\telegram\ext\_extbot.py", line 649, in get_updates
    updates = await super().get_updates(
              ^^^^^^^^^^^^^^^^^^^^^^^^^^
  File "C:\Users\Стас\AppData\Local\Programs\Python\Python312\Lib\site-packages\telegram\_bot.py", line 4366, in get_updates
    await self._post(
  File "C:\Users\Стас\AppData\Local\Programs\Python\Python312\Lib\site-packages\telegram\_bot.py", line 623, in _post
    return await self._do_post(
           ^^^^^^^^^^^^^^^^^^^^
  File "C:\Users\Стас\AppData\Local\Programs\Python\Python312\Lib\site-packages\telegram\ext\_extbot.py", line 355, in _do_post
    return await super()._do_post(
           ^^^^^^^^^^^^^^^^^^^^^^^
  File "C:\Users\Стас\AppData\Local\Programs\Python\Python312\Lib\site-packages\telegram\_bot.py", line 652, in _do_post
    result = await request.post(
             ^^^^^^^^^^^^^^^^^^^
  File "C:\Users\Стас\AppData\Local\Programs\Python\Python312\Lib\site-packages\telegram\request\_baserequest.py", line 201, in post
    result = await self._request_wrapper(
             ^^^^^^^^^^^^^^^^^^^^^^^^^^^^
  File "C:\Users\Стас\AppData\Local\Programs\Python\Python312\Lib\site-packages\telegram\request\_baserequest.py", line 333, in _request_wrapper
    code, payload = await self.do_request(
                    ^^^^^^^^^^^^^^^^^^^^^^
  File "C:\Users\Стас\AppData\Local\Programs\Python\Python312\Lib\site-packages\telegram\request\_httpxrequest.py", line 316, in do_request
    raise NetworkError(f"httpx.{err.__class__.__name__}: {err}") from err
telegram.error.NetworkError: httpx.ReadError: 
2024-10-22 15:46:04,718 - telegram.ext.Application - ERROR - No error handlers are registered, logging exception.
Traceback (most recent call last):
  File "C:\Users\Стас\AppData\Local\Programs\Python\Python312\Lib\site-packages\httpx\_transports\default.py", line 72, in map_httpcore_exceptions
    yield
  File "C:\Users\Стас\AppData\Local\Programs\Python\Python312\Lib\site-packages\httpx\_transports\default.py", line 377, in handle_async_request
    resp = await self._pool.handle_async_request(req)
           ^^^^^^^^^^^^^^^^^^^^^^^^^^^^^^^^^^^^^^^^^^
  File "C:\Users\Стас\AppData\Local\Programs\Python\Python312\Lib\site-packages\httpcore\_async\connection_pool.py", line 216, in handle_async_request
    raise exc from None
  File "C:\Users\Стас\AppData\Local\Programs\Python\Python312\Lib\site-packages\httpcore\_async\connection_pool.py", line 196, in handle_async_request
    response = await connection.handle_async_request(
               ^^^^^^^^^^^^^^^^^^^^^^^^^^^^^^^^^^^^^^
  File "C:\Users\Стас\AppData\Local\Programs\Python\Python312\Lib\site-packages\httpcore\_async\connection.py", line 99, in handle_async_request
    raise exc
  File "C:\Users\Стас\AppData\Local\Programs\Python\Python312\Lib\site-packages\httpcore\_async\connection.py", line 76, in handle_async_request
    stream = await self._connect(request)
             ^^^^^^^^^^^^^^^^^^^^^^^^^^^^
  File "C:\Users\Стас\AppData\Local\Programs\Python\Python312\Lib\site-packages\httpcore\_async\connection.py", line 122, in _connect
    stream = await self._network_backend.connect_tcp(**kwargs)
             ^^^^^^^^^^^^^^^^^^^^^^^^^^^^^^^^^^^^^^^^^^^^^^^^^
  File "C:\Users\Стас\AppData\Local\Programs\Python\Python312\Lib\site-packages\httpcore\_backends\auto.py", line 30, in connect_tcp
    return await self._backend.connect_tcp(
           ^^^^^^^^^^^^^^^^^^^^^^^^^^^^^^^^
  File "C:\Users\Стас\AppData\Local\Programs\Python\Python312\Lib\site-packages\httpcore\_backends\anyio.py", line 115, in connect_tcp
    with map_exceptions(exc_map):
  File "C:\Users\Стас\AppData\Local\Programs\Python\Python312\Lib\contextlib.py", line 158, in __exit__
    self.gen.throw(value)
  File "C:\Users\Стас\AppData\Local\Programs\Python\Python312\Lib\site-packages\httpcore\_exceptions.py", line 14, in map_exceptions
    raise to_exc(exc) from exc
httpcore.ConnectError: [Errno 11001] getaddrinfo failed

The above exception was the direct cause of the following exception:

Traceback (most recent call last):
  File "C:\Users\Стас\AppData\Local\Programs\Python\Python312\Lib\site-packages\telegram\request\_httpxrequest.py", line 292, in do_request
    res = await self._client.request(
          ^^^^^^^^^^^^^^^^^^^^^^^^^^^
  File "C:\Users\Стас\AppData\Local\Programs\Python\Python312\Lib\site-packages\httpx\_client.py", line 1585, in request
    return await self.send(request, auth=auth, follow_redirects=follow_redirects)
           ^^^^^^^^^^^^^^^^^^^^^^^^^^^^^^^^^^^^^^^^^^^^^^^^^^^^^^^^^^^^^^^^^^^^^^
  File "C:\Users\Стас\AppData\Local\Programs\Python\Python312\Lib\site-packages\httpx\_client.py", line 1674, in send
    response = await self._send_handling_auth(
               ^^^^^^^^^^^^^^^^^^^^^^^^^^^^^^^
  File "C:\Users\Стас\AppData\Local\Programs\Python\Python312\Lib\site-packages\httpx\_client.py", line 1702, in _send_handling_auth
    response = await self._send_handling_redirects(
               ^^^^^^^^^^^^^^^^^^^^^^^^^^^^^^^^^^^^
  File "C:\Users\Стас\AppData\Local\Programs\Python\Python312\Lib\site-packages\httpx\_client.py", line 1739, in _send_handling_redirects
    response = await self._send_single_request(request)
               ^^^^^^^^^^^^^^^^^^^^^^^^^^^^^^^^^^^^^^^^
  File "C:\Users\Стас\AppData\Local\Programs\Python\Python312\Lib\site-packages\httpx\_client.py", line 1776, in _send_single_request
    response = await transport.handle_async_request(request)
               ^^^^^^^^^^^^^^^^^^^^^^^^^^^^^^^^^^^^^^^^^^^^^
  File "C:\Users\Стас\AppData\Local\Programs\Python\Python312\Lib\site-packages\httpx\_transports\default.py", line 376, in handle_async_request
    with map_httpcore_exceptions():
  File "C:\Users\Стас\AppData\Local\Programs\Python\Python312\Lib\contextlib.py", line 158, in __exit__
    self.gen.throw(value)
  File "C:\Users\Стас\AppData\Local\Programs\Python\Python312\Lib\site-packages\httpx\_transports\default.py", line 89, in map_httpcore_exceptions
    raise mapped_exc(message) from exc
httpx.ConnectError: [Errno 11001] getaddrinfo failed

The above exception was the direct cause of the following exception:

Traceback (most recent call last):
  File "C:\Users\Стас\AppData\Local\Programs\Python\Python312\Lib\site-packages\telegram\ext\_updater.py", line 753, in _network_loop_retry
    if not await do_action():
           ^^^^^^^^^^^^^^^^^
  File "C:\Users\Стас\AppData\Local\Programs\Python\Python312\Lib\site-packages\telegram\ext\_updater.py", line 747, in do_action
    return action_cb_task.result()
           ^^^^^^^^^^^^^^^^^^^^^^^
  File "C:\Users\Стас\AppData\Local\Programs\Python\Python312\Lib\site-packages\telegram\ext\_updater.py", line 377, in polling_action_cb
    updates = await self.bot.get_updates(
              ^^^^^^^^^^^^^^^^^^^^^^^^^^^
  File "C:\Users\Стас\AppData\Local\Programs\Python\Python312\Lib\site-packages\telegram\ext\_extbot.py", line 649, in get_updates
    updates = await super().get_updates(
              ^^^^^^^^^^^^^^^^^^^^^^^^^^
  File "C:\Users\Стас\AppData\Local\Programs\Python\Python312\Lib\site-packages\telegram\_bot.py", line 4366, in get_updates
    await self._post(
  File "C:\Users\Стас\AppData\Local\Programs\Python\Python312\Lib\site-packages\telegram\_bot.py", line 623, in _post
    return await self._do_post(
           ^^^^^^^^^^^^^^^^^^^^
  File "C:\Users\Стас\AppData\Local\Programs\Python\Python312\Lib\site-packages\telegram\ext\_extbot.py", line 355, in _do_post
    return await super()._do_post(
           ^^^^^^^^^^^^^^^^^^^^^^^
  File "C:\Users\Стас\AppData\Local\Programs\Python\Python312\Lib\site-packages\telegram\_bot.py", line 652, in _do_post
    result = await request.post(
             ^^^^^^^^^^^^^^^^^^^
  File "C:\Users\Стас\AppData\Local\Programs\Python\Python312\Lib\site-packages\telegram\request\_baserequest.py", line 201, in post
    result = await self._request_wrapper(
             ^^^^^^^^^^^^^^^^^^^^^^^^^^^^
  File "C:\Users\Стас\AppData\Local\Programs\Python\Python312\Lib\site-packages\telegram\request\_baserequest.py", line 333, in _request_wrapper
    code, payload = await self.do_request(
                    ^^^^^^^^^^^^^^^^^^^^^^
  File "C:\Users\Стас\AppData\Local\Programs\Python\Python312\Lib\site-packages\telegram\request\_httpxrequest.py", line 316, in do_request
    raise NetworkError(f"httpx.{err.__class__.__name__}: {err}") from err
telegram.error.NetworkError: httpx.ConnectError: [Errno 11001] getaddrinfo failed
2024-10-22 15:46:06,228 - telegram.ext.Application - ERROR - No error handlers are registered, logging exception.
Traceback (most recent call last):
  File "C:\Users\Стас\AppData\Local\Programs\Python\Python312\Lib\site-packages\httpx\_transports\default.py", line 72, in map_httpcore_exceptions
    yield
  File "C:\Users\Стас\AppData\Local\Programs\Python\Python312\Lib\site-packages\httpx\_transports\default.py", line 377, in handle_async_request
    resp = await self._pool.handle_async_request(req)
           ^^^^^^^^^^^^^^^^^^^^^^^^^^^^^^^^^^^^^^^^^^
  File "C:\Users\Стас\AppData\Local\Programs\Python\Python312\Lib\site-packages\httpcore\_async\connection_pool.py", line 216, in handle_async_request
    raise exc from None
  File "C:\Users\Стас\AppData\Local\Programs\Python\Python312\Lib\site-packages\httpcore\_async\connection_pool.py", line 196, in handle_async_request
    response = await connection.handle_async_request(
               ^^^^^^^^^^^^^^^^^^^^^^^^^^^^^^^^^^^^^^
  File "C:\Users\Стас\AppData\Local\Programs\Python\Python312\Lib\site-packages\httpcore\_async\connection.py", line 99, in handle_async_request
    raise exc
  File "C:\Users\Стас\AppData\Local\Programs\Python\Python312\Lib\site-packages\httpcore\_async\connection.py", line 76, in handle_async_request
    stream = await self._connect(request)
             ^^^^^^^^^^^^^^^^^^^^^^^^^^^^
  File "C:\Users\Стас\AppData\Local\Programs\Python\Python312\Lib\site-packages\httpcore\_async\connection.py", line 122, in _connect
    stream = await self._network_backend.connect_tcp(**kwargs)
             ^^^^^^^^^^^^^^^^^^^^^^^^^^^^^^^^^^^^^^^^^^^^^^^^^
  File "C:\Users\Стас\AppData\Local\Programs\Python\Python312\Lib\site-packages\httpcore\_backends\auto.py", line 30, in connect_tcp
    return await self._backend.connect_tcp(
           ^^^^^^^^^^^^^^^^^^^^^^^^^^^^^^^^
  File "C:\Users\Стас\AppData\Local\Programs\Python\Python312\Lib\site-packages\httpcore\_backends\anyio.py", line 115, in connect_tcp
    with map_exceptions(exc_map):
  File "C:\Users\Стас\AppData\Local\Programs\Python\Python312\Lib\contextlib.py", line 158, in __exit__
    self.gen.throw(value)
  File "C:\Users\Стас\AppData\Local\Programs\Python\Python312\Lib\site-packages\httpcore\_exceptions.py", line 14, in map_exceptions
    raise to_exc(exc) from exc
httpcore.ConnectError: [Errno 11001] getaddrinfo failed

The above exception was the direct cause of the following exception:

Traceback (most recent call last):
  File "C:\Users\Стас\AppData\Local\Programs\Python\Python312\Lib\site-packages\telegram\request\_httpxrequest.py", line 292, in do_request
    res = await self._client.request(
          ^^^^^^^^^^^^^^^^^^^^^^^^^^^
  File "C:\Users\Стас\AppData\Local\Programs\Python\Python312\Lib\site-packages\httpx\_client.py", line 1585, in request
    return await self.send(request, auth=auth, follow_redirects=follow_redirects)
           ^^^^^^^^^^^^^^^^^^^^^^^^^^^^^^^^^^^^^^^^^^^^^^^^^^^^^^^^^^^^^^^^^^^^^^
  File "C:\Users\Стас\AppData\Local\Programs\Python\Python312\Lib\site-packages\httpx\_client.py", line 1674, in send
    response = await self._send_handling_auth(
               ^^^^^^^^^^^^^^^^^^^^^^^^^^^^^^^
  File "C:\Users\Стас\AppData\Local\Programs\Python\Python312\Lib\site-packages\httpx\_client.py", line 1702, in _send_handling_auth
    response = await self._send_handling_redirects(
               ^^^^^^^^^^^^^^^^^^^^^^^^^^^^^^^^^^^^
  File "C:\Users\Стас\AppData\Local\Programs\Python\Python312\Lib\site-packages\httpx\_client.py", line 1739, in _send_handling_redirects
    response = await self._send_single_request(request)
               ^^^^^^^^^^^^^^^^^^^^^^^^^^^^^^^^^^^^^^^^
  File "C:\Users\Стас\AppData\Local\Programs\Python\Python312\Lib\site-packages\httpx\_client.py", line 1776, in _send_single_request
    response = await transport.handle_async_request(request)
               ^^^^^^^^^^^^^^^^^^^^^^^^^^^^^^^^^^^^^^^^^^^^^
  File "C:\Users\Стас\AppData\Local\Programs\Python\Python312\Lib\site-packages\httpx\_transports\default.py", line 376, in handle_async_request
    with map_httpcore_exceptions():
  File "C:\Users\Стас\AppData\Local\Programs\Python\Python312\Lib\contextlib.py", line 158, in __exit__
    self.gen.throw(value)
  File "C:\Users\Стас\AppData\Local\Programs\Python\Python312\Lib\site-packages\httpx\_transports\default.py", line 89, in map_httpcore_exceptions
    raise mapped_exc(message) from exc
httpx.ConnectError: [Errno 11001] getaddrinfo failed

The above exception was the direct cause of the following exception:

Traceback (most recent call last):
  File "C:\Users\Стас\AppData\Local\Programs\Python\Python312\Lib\site-packages\telegram\ext\_updater.py", line 753, in _network_loop_retry
    if not await do_action():
           ^^^^^^^^^^^^^^^^^
  File "C:\Users\Стас\AppData\Local\Programs\Python\Python312\Lib\site-packages\telegram\ext\_updater.py", line 747, in do_action
    return action_cb_task.result()
           ^^^^^^^^^^^^^^^^^^^^^^^
  File "C:\Users\Стас\AppData\Local\Programs\Python\Python312\Lib\site-packages\telegram\ext\_updater.py", line 377, in polling_action_cb
    updates = await self.bot.get_updates(
              ^^^^^^^^^^^^^^^^^^^^^^^^^^^
  File "C:\Users\Стас\AppData\Local\Programs\Python\Python312\Lib\site-packages\telegram\ext\_extbot.py", line 649, in get_updates
    updates = await super().get_updates(
              ^^^^^^^^^^^^^^^^^^^^^^^^^^
  File "C:\Users\Стас\AppData\Local\Programs\Python\Python312\Lib\site-packages\telegram\_bot.py", line 4366, in get_updates
    await self._post(
  File "C:\Users\Стас\AppData\Local\Programs\Python\Python312\Lib\site-packages\telegram\_bot.py", line 623, in _post
    return await self._do_post(
           ^^^^^^^^^^^^^^^^^^^^
  File "C:\Users\Стас\AppData\Local\Programs\Python\Python312\Lib\site-packages\telegram\ext\_extbot.py", line 355, in _do_post
    return await super()._do_post(
           ^^^^^^^^^^^^^^^^^^^^^^^
  File "C:\Users\Стас\AppData\Local\Programs\Python\Python312\Lib\site-packages\telegram\_bot.py", line 652, in _do_post
    result = await request.post(
             ^^^^^^^^^^^^^^^^^^^
  File "C:\Users\Стас\AppData\Local\Programs\Python\Python312\Lib\site-packages\telegram\request\_baserequest.py", line 201, in post
    result = await self._request_wrapper(
             ^^^^^^^^^^^^^^^^^^^^^^^^^^^^
  File "C:\Users\Стас\AppData\Local\Programs\Python\Python312\Lib\site-packages\telegram\request\_baserequest.py", line 333, in _request_wrapper
    code, payload = await self.do_request(
                    ^^^^^^^^^^^^^^^^^^^^^^
  File "C:\Users\Стас\AppData\Local\Programs\Python\Python312\Lib\site-packages\telegram\request\_httpxrequest.py", line 316, in do_request
    raise NetworkError(f"httpx.{err.__class__.__name__}: {err}") from err
telegram.error.NetworkError: httpx.ConnectError: [Errno 11001] getaddrinfo failed
2024-10-22 15:46:08,490 - telegram.ext.Application - ERROR - No error handlers are registered, logging exception.
Traceback (most recent call last):
  File "C:\Users\Стас\AppData\Local\Programs\Python\Python312\Lib\site-packages\httpx\_transports\default.py", line 72, in map_httpcore_exceptions
    yield
  File "C:\Users\Стас\AppData\Local\Programs\Python\Python312\Lib\site-packages\httpx\_transports\default.py", line 377, in handle_async_request
    resp = await self._pool.handle_async_request(req)
           ^^^^^^^^^^^^^^^^^^^^^^^^^^^^^^^^^^^^^^^^^^
  File "C:\Users\Стас\AppData\Local\Programs\Python\Python312\Lib\site-packages\httpcore\_async\connection_pool.py", line 216, in handle_async_request
    raise exc from None
  File "C:\Users\Стас\AppData\Local\Programs\Python\Python312\Lib\site-packages\httpcore\_async\connection_pool.py", line 196, in handle_async_request
    response = await connection.handle_async_request(
               ^^^^^^^^^^^^^^^^^^^^^^^^^^^^^^^^^^^^^^
  File "C:\Users\Стас\AppData\Local\Programs\Python\Python312\Lib\site-packages\httpcore\_async\connection.py", line 99, in handle_async_request
    raise exc
  File "C:\Users\Стас\AppData\Local\Programs\Python\Python312\Lib\site-packages\httpcore\_async\connection.py", line 76, in handle_async_request
    stream = await self._connect(request)
             ^^^^^^^^^^^^^^^^^^^^^^^^^^^^
  File "C:\Users\Стас\AppData\Local\Programs\Python\Python312\Lib\site-packages\httpcore\_async\connection.py", line 122, in _connect
    stream = await self._network_backend.connect_tcp(**kwargs)
             ^^^^^^^^^^^^^^^^^^^^^^^^^^^^^^^^^^^^^^^^^^^^^^^^^
  File "C:\Users\Стас\AppData\Local\Programs\Python\Python312\Lib\site-packages\httpcore\_backends\auto.py", line 30, in connect_tcp
    return await self._backend.connect_tcp(
           ^^^^^^^^^^^^^^^^^^^^^^^^^^^^^^^^
  File "C:\Users\Стас\AppData\Local\Programs\Python\Python312\Lib\site-packages\httpcore\_backends\anyio.py", line 115, in connect_tcp
    with map_exceptions(exc_map):
  File "C:\Users\Стас\AppData\Local\Programs\Python\Python312\Lib\contextlib.py", line 158, in __exit__
    self.gen.throw(value)
  File "C:\Users\Стас\AppData\Local\Programs\Python\Python312\Lib\site-packages\httpcore\_exceptions.py", line 14, in map_exceptions
    raise to_exc(exc) from exc
httpcore.ConnectError: [Errno 11001] getaddrinfo failed

The above exception was the direct cause of the following exception:

Traceback (most recent call last):
  File "C:\Users\Стас\AppData\Local\Programs\Python\Python312\Lib\site-packages\telegram\request\_httpxrequest.py", line 292, in do_request
    res = await self._client.request(
          ^^^^^^^^^^^^^^^^^^^^^^^^^^^
  File "C:\Users\Стас\AppData\Local\Programs\Python\Python312\Lib\site-packages\httpx\_client.py", line 1585, in request
    return await self.send(request, auth=auth, follow_redirects=follow_redirects)
           ^^^^^^^^^^^^^^^^^^^^^^^^^^^^^^^^^^^^^^^^^^^^^^^^^^^^^^^^^^^^^^^^^^^^^^
  File "C:\Users\Стас\AppData\Local\Programs\Python\Python312\Lib\site-packages\httpx\_client.py", line 1674, in send
    response = await self._send_handling_auth(
               ^^^^^^^^^^^^^^^^^^^^^^^^^^^^^^^
  File "C:\Users\Стас\AppData\Local\Programs\Python\Python312\Lib\site-packages\httpx\_client.py", line 1702, in _send_handling_auth
    response = await self._send_handling_redirects(
               ^^^^^^^^^^^^^^^^^^^^^^^^^^^^^^^^^^^^
  File "C:\Users\Стас\AppData\Local\Programs\Python\Python312\Lib\site-packages\httpx\_client.py", line 1739, in _send_handling_redirects
    response = await self._send_single_request(request)
               ^^^^^^^^^^^^^^^^^^^^^^^^^^^^^^^^^^^^^^^^
  File "C:\Users\Стас\AppData\Local\Programs\Python\Python312\Lib\site-packages\httpx\_client.py", line 1776, in _send_single_request
    response = await transport.handle_async_request(request)
               ^^^^^^^^^^^^^^^^^^^^^^^^^^^^^^^^^^^^^^^^^^^^^
  File "C:\Users\Стас\AppData\Local\Programs\Python\Python312\Lib\site-packages\httpx\_transports\default.py", line 376, in handle_async_request
    with map_httpcore_exceptions():
  File "C:\Users\Стас\AppData\Local\Programs\Python\Python312\Lib\contextlib.py", line 158, in __exit__
    self.gen.throw(value)
  File "C:\Users\Стас\AppData\Local\Programs\Python\Python312\Lib\site-packages\httpx\_transports\default.py", line 89, in map_httpcore_exceptions
    raise mapped_exc(message) from exc
httpx.ConnectError: [Errno 11001] getaddrinfo failed

The above exception was the direct cause of the following exception:

Traceback (most recent call last):
  File "C:\Users\Стас\AppData\Local\Programs\Python\Python312\Lib\site-packages\telegram\ext\_updater.py", line 753, in _network_loop_retry
    if not await do_action():
           ^^^^^^^^^^^^^^^^^
  File "C:\Users\Стас\AppData\Local\Programs\Python\Python312\Lib\site-packages\telegram\ext\_updater.py", line 747, in do_action
    return action_cb_task.result()
           ^^^^^^^^^^^^^^^^^^^^^^^
  File "C:\Users\Стас\AppData\Local\Programs\Python\Python312\Lib\site-packages\telegram\ext\_updater.py", line 377, in polling_action_cb
    updates = await self.bot.get_updates(
              ^^^^^^^^^^^^^^^^^^^^^^^^^^^
  File "C:\Users\Стас\AppData\Local\Programs\Python\Python312\Lib\site-packages\telegram\ext\_extbot.py", line 649, in get_updates
    updates = await super().get_updates(
              ^^^^^^^^^^^^^^^^^^^^^^^^^^
  File "C:\Users\Стас\AppData\Local\Programs\Python\Python312\Lib\site-packages\telegram\_bot.py", line 4366, in get_updates
    await self._post(
  File "C:\Users\Стас\AppData\Local\Programs\Python\Python312\Lib\site-packages\telegram\_bot.py", line 623, in _post
    return await self._do_post(
           ^^^^^^^^^^^^^^^^^^^^
  File "C:\Users\Стас\AppData\Local\Programs\Python\Python312\Lib\site-packages\telegram\ext\_extbot.py", line 355, in _do_post
    return await super()._do_post(
           ^^^^^^^^^^^^^^^^^^^^^^^
  File "C:\Users\Стас\AppData\Local\Programs\Python\Python312\Lib\site-packages\telegram\_bot.py", line 652, in _do_post
    result = await request.post(
             ^^^^^^^^^^^^^^^^^^^
  File "C:\Users\Стас\AppData\Local\Programs\Python\Python312\Lib\site-packages\telegram\request\_baserequest.py", line 201, in post
    result = await self._request_wrapper(
             ^^^^^^^^^^^^^^^^^^^^^^^^^^^^
  File "C:\Users\Стас\AppData\Local\Programs\Python\Python312\Lib\site-packages\telegram\request\_baserequest.py", line 333, in _request_wrapper
    code, payload = await self.do_request(
                    ^^^^^^^^^^^^^^^^^^^^^^
  File "C:\Users\Стас\AppData\Local\Programs\Python\Python312\Lib\site-packages\telegram\request\_httpxrequest.py", line 316, in do_request
    raise NetworkError(f"httpx.{err.__class__.__name__}: {err}") from err
telegram.error.NetworkError: httpx.ConnectError: [Errno 11001] getaddrinfo failed
2024-10-22 15:46:11,874 - telegram.ext.Application - ERROR - No error handlers are registered, logging exception.
Traceback (most recent call last):
  File "C:\Users\Стас\AppData\Local\Programs\Python\Python312\Lib\site-packages\httpx\_transports\default.py", line 72, in map_httpcore_exceptions
    yield
  File "C:\Users\Стас\AppData\Local\Programs\Python\Python312\Lib\site-packages\httpx\_transports\default.py", line 377, in handle_async_request
    resp = await self._pool.handle_async_request(req)
           ^^^^^^^^^^^^^^^^^^^^^^^^^^^^^^^^^^^^^^^^^^
  File "C:\Users\Стас\AppData\Local\Programs\Python\Python312\Lib\site-packages\httpcore\_async\connection_pool.py", line 216, in handle_async_request
    raise exc from None
  File "C:\Users\Стас\AppData\Local\Programs\Python\Python312\Lib\site-packages\httpcore\_async\connection_pool.py", line 196, in handle_async_request
    response = await connection.handle_async_request(
               ^^^^^^^^^^^^^^^^^^^^^^^^^^^^^^^^^^^^^^
  File "C:\Users\Стас\AppData\Local\Programs\Python\Python312\Lib\site-packages\httpcore\_async\connection.py", line 99, in handle_async_request
    raise exc
  File "C:\Users\Стас\AppData\Local\Programs\Python\Python312\Lib\site-packages\httpcore\_async\connection.py", line 76, in handle_async_request
    stream = await self._connect(request)
             ^^^^^^^^^^^^^^^^^^^^^^^^^^^^
  File "C:\Users\Стас\AppData\Local\Programs\Python\Python312\Lib\site-packages\httpcore\_async\connection.py", line 122, in _connect
    stream = await self._network_backend.connect_tcp(**kwargs)
             ^^^^^^^^^^^^^^^^^^^^^^^^^^^^^^^^^^^^^^^^^^^^^^^^^
  File "C:\Users\Стас\AppData\Local\Programs\Python\Python312\Lib\site-packages\httpcore\_backends\auto.py", line 30, in connect_tcp
    return await self._backend.connect_tcp(
           ^^^^^^^^^^^^^^^^^^^^^^^^^^^^^^^^
  File "C:\Users\Стас\AppData\Local\Programs\Python\Python312\Lib\site-packages\httpcore\_backends\anyio.py", line 115, in connect_tcp
    with map_exceptions(exc_map):
  File "C:\Users\Стас\AppData\Local\Programs\Python\Python312\Lib\contextlib.py", line 158, in __exit__
    self.gen.throw(value)
  File "C:\Users\Стас\AppData\Local\Programs\Python\Python312\Lib\site-packages\httpcore\_exceptions.py", line 14, in map_exceptions
    raise to_exc(exc) from exc
httpcore.ConnectError: [Errno 11001] getaddrinfo failed

The above exception was the direct cause of the following exception:

Traceback (most recent call last):
  File "C:\Users\Стас\AppData\Local\Programs\Python\Python312\Lib\site-packages\telegram\request\_httpxrequest.py", line 292, in do_request
    res = await self._client.request(
          ^^^^^^^^^^^^^^^^^^^^^^^^^^^
  File "C:\Users\Стас\AppData\Local\Programs\Python\Python312\Lib\site-packages\httpx\_client.py", line 1585, in request
    return await self.send(request, auth=auth, follow_redirects=follow_redirects)
           ^^^^^^^^^^^^^^^^^^^^^^^^^^^^^^^^^^^^^^^^^^^^^^^^^^^^^^^^^^^^^^^^^^^^^^
  File "C:\Users\Стас\AppData\Local\Programs\Python\Python312\Lib\site-packages\httpx\_client.py", line 1674, in send
    response = await self._send_handling_auth(
               ^^^^^^^^^^^^^^^^^^^^^^^^^^^^^^^
  File "C:\Users\Стас\AppData\Local\Programs\Python\Python312\Lib\site-packages\httpx\_client.py", line 1702, in _send_handling_auth
    response = await self._send_handling_redirects(
               ^^^^^^^^^^^^^^^^^^^^^^^^^^^^^^^^^^^^
  File "C:\Users\Стас\AppData\Local\Programs\Python\Python312\Lib\site-packages\httpx\_client.py", line 1739, in _send_handling_redirects
    response = await self._send_single_request(request)
               ^^^^^^^^^^^^^^^^^^^^^^^^^^^^^^^^^^^^^^^^
  File "C:\Users\Стас\AppData\Local\Programs\Python\Python312\Lib\site-packages\httpx\_client.py", line 1776, in _send_single_request
    response = await transport.handle_async_request(request)
               ^^^^^^^^^^^^^^^^^^^^^^^^^^^^^^^^^^^^^^^^^^^^^
  File "C:\Users\Стас\AppData\Local\Programs\Python\Python312\Lib\site-packages\httpx\_transports\default.py", line 376, in handle_async_request
    with map_httpcore_exceptions():
  File "C:\Users\Стас\AppData\Local\Programs\Python\Python312\Lib\contextlib.py", line 158, in __exit__
    self.gen.throw(value)
  File "C:\Users\Стас\AppData\Local\Programs\Python\Python312\Lib\site-packages\httpx\_transports\default.py", line 89, in map_httpcore_exceptions
    raise mapped_exc(message) from exc
httpx.ConnectError: [Errno 11001] getaddrinfo failed

The above exception was the direct cause of the following exception:

Traceback (most recent call last):
  File "C:\Users\Стас\AppData\Local\Programs\Python\Python312\Lib\site-packages\telegram\ext\_updater.py", line 753, in _network_loop_retry
    if not await do_action():
           ^^^^^^^^^^^^^^^^^
  File "C:\Users\Стас\AppData\Local\Programs\Python\Python312\Lib\site-packages\telegram\ext\_updater.py", line 747, in do_action
    return action_cb_task.result()
           ^^^^^^^^^^^^^^^^^^^^^^^
  File "C:\Users\Стас\AppData\Local\Programs\Python\Python312\Lib\site-packages\telegram\ext\_updater.py", line 377, in polling_action_cb
    updates = await self.bot.get_updates(
              ^^^^^^^^^^^^^^^^^^^^^^^^^^^
  File "C:\Users\Стас\AppData\Local\Programs\Python\Python312\Lib\site-packages\telegram\ext\_extbot.py", line 649, in get_updates
    updates = await super().get_updates(
              ^^^^^^^^^^^^^^^^^^^^^^^^^^
  File "C:\Users\Стас\AppData\Local\Programs\Python\Python312\Lib\site-packages\telegram\_bot.py", line 4366, in get_updates
    await self._post(
  File "C:\Users\Стас\AppData\Local\Programs\Python\Python312\Lib\site-packages\telegram\_bot.py", line 623, in _post
    return await self._do_post(
           ^^^^^^^^^^^^^^^^^^^^
  File "C:\Users\Стас\AppData\Local\Programs\Python\Python312\Lib\site-packages\telegram\ext\_extbot.py", line 355, in _do_post
    return await super()._do_post(
           ^^^^^^^^^^^^^^^^^^^^^^^
  File "C:\Users\Стас\AppData\Local\Programs\Python\Python312\Lib\site-packages\telegram\_bot.py", line 652, in _do_post
    result = await request.post(
             ^^^^^^^^^^^^^^^^^^^
  File "C:\Users\Стас\AppData\Local\Programs\Python\Python312\Lib\site-packages\telegram\request\_baserequest.py", line 201, in post
    result = await self._request_wrapper(
             ^^^^^^^^^^^^^^^^^^^^^^^^^^^^
  File "C:\Users\Стас\AppData\Local\Programs\Python\Python312\Lib\site-packages\telegram\request\_baserequest.py", line 333, in _request_wrapper
    code, payload = await self.do_request(
                    ^^^^^^^^^^^^^^^^^^^^^^
  File "C:\Users\Стас\AppData\Local\Programs\Python\Python312\Lib\site-packages\telegram\request\_httpxrequest.py", line 316, in do_request
    raise NetworkError(f"httpx.{err.__class__.__name__}: {err}") from err
telegram.error.NetworkError: httpx.ConnectError: [Errno 11001] getaddrinfo failed
2024-10-22 15:46:16,959 - telegram.ext.Application - ERROR - No error handlers are registered, logging exception.
Traceback (most recent call last):
  File "C:\Users\Стас\AppData\Local\Programs\Python\Python312\Lib\site-packages\httpx\_transports\default.py", line 72, in map_httpcore_exceptions
    yield
  File "C:\Users\Стас\AppData\Local\Programs\Python\Python312\Lib\site-packages\httpx\_transports\default.py", line 377, in handle_async_request
    resp = await self._pool.handle_async_request(req)
           ^^^^^^^^^^^^^^^^^^^^^^^^^^^^^^^^^^^^^^^^^^
  File "C:\Users\Стас\AppData\Local\Programs\Python\Python312\Lib\site-packages\httpcore\_async\connection_pool.py", line 216, in handle_async_request
    raise exc from None
  File "C:\Users\Стас\AppData\Local\Programs\Python\Python312\Lib\site-packages\httpcore\_async\connection_pool.py", line 196, in handle_async_request
    response = await connection.handle_async_request(
               ^^^^^^^^^^^^^^^^^^^^^^^^^^^^^^^^^^^^^^
  File "C:\Users\Стас\AppData\Local\Programs\Python\Python312\Lib\site-packages\httpcore\_async\connection.py", line 99, in handle_async_request
    raise exc
  File "C:\Users\Стас\AppData\Local\Programs\Python\Python312\Lib\site-packages\httpcore\_async\connection.py", line 76, in handle_async_request
    stream = await self._connect(request)
             ^^^^^^^^^^^^^^^^^^^^^^^^^^^^
  File "C:\Users\Стас\AppData\Local\Programs\Python\Python312\Lib\site-packages\httpcore\_async\connection.py", line 122, in _connect
    stream = await self._network_backend.connect_tcp(**kwargs)
             ^^^^^^^^^^^^^^^^^^^^^^^^^^^^^^^^^^^^^^^^^^^^^^^^^
  File "C:\Users\Стас\AppData\Local\Programs\Python\Python312\Lib\site-packages\httpcore\_backends\auto.py", line 30, in connect_tcp
    return await self._backend.connect_tcp(
           ^^^^^^^^^^^^^^^^^^^^^^^^^^^^^^^^
  File "C:\Users\Стас\AppData\Local\Programs\Python\Python312\Lib\site-packages\httpcore\_backends\anyio.py", line 115, in connect_tcp
    with map_exceptions(exc_map):
  File "C:\Users\Стас\AppData\Local\Programs\Python\Python312\Lib\contextlib.py", line 158, in __exit__
    self.gen.throw(value)
  File "C:\Users\Стас\AppData\Local\Programs\Python\Python312\Lib\site-packages\httpcore\_exceptions.py", line 14, in map_exceptions
    raise to_exc(exc) from exc
httpcore.ConnectError: [Errno 11001] getaddrinfo failed

The above exception was the direct cause of the following exception:

Traceback (most recent call last):
  File "C:\Users\Стас\AppData\Local\Programs\Python\Python312\Lib\site-packages\telegram\request\_httpxrequest.py", line 292, in do_request
    res = await self._client.request(
          ^^^^^^^^^^^^^^^^^^^^^^^^^^^
  File "C:\Users\Стас\AppData\Local\Programs\Python\Python312\Lib\site-packages\httpx\_client.py", line 1585, in request
    return await self.send(request, auth=auth, follow_redirects=follow_redirects)
           ^^^^^^^^^^^^^^^^^^^^^^^^^^^^^^^^^^^^^^^^^^^^^^^^^^^^^^^^^^^^^^^^^^^^^^
  File "C:\Users\Стас\AppData\Local\Programs\Python\Python312\Lib\site-packages\httpx\_client.py", line 1674, in send
    response = await self._send_handling_auth(
               ^^^^^^^^^^^^^^^^^^^^^^^^^^^^^^^
  File "C:\Users\Стас\AppData\Local\Programs\Python\Python312\Lib\site-packages\httpx\_client.py", line 1702, in _send_handling_auth
    response = await self._send_handling_redirects(
               ^^^^^^^^^^^^^^^^^^^^^^^^^^^^^^^^^^^^
  File "C:\Users\Стас\AppData\Local\Programs\Python\Python312\Lib\site-packages\httpx\_client.py", line 1739, in _send_handling_redirects
    response = await self._send_single_request(request)
               ^^^^^^^^^^^^^^^^^^^^^^^^^^^^^^^^^^^^^^^^
  File "C:\Users\Стас\AppData\Local\Programs\Python\Python312\Lib\site-packages\httpx\_client.py", line 1776, in _send_single_request
    response = await transport.handle_async_request(request)
               ^^^^^^^^^^^^^^^^^^^^^^^^^^^^^^^^^^^^^^^^^^^^^
  File "C:\Users\Стас\AppData\Local\Programs\Python\Python312\Lib\site-packages\httpx\_transports\default.py", line 376, in handle_async_request
    with map_httpcore_exceptions():
  File "C:\Users\Стас\AppData\Local\Programs\Python\Python312\Lib\contextlib.py", line 158, in __exit__
    self.gen.throw(value)
  File "C:\Users\Стас\AppData\Local\Programs\Python\Python312\Lib\site-packages\httpx\_transports\default.py", line 89, in map_httpcore_exceptions
    raise mapped_exc(message) from exc
httpx.ConnectError: [Errno 11001] getaddrinfo failed

The above exception was the direct cause of the following exception:

Traceback (most recent call last):
  File "C:\Users\Стас\AppData\Local\Programs\Python\Python312\Lib\site-packages\telegram\ext\_updater.py", line 753, in _network_loop_retry
    if not await do_action():
           ^^^^^^^^^^^^^^^^^
  File "C:\Users\Стас\AppData\Local\Programs\Python\Python312\Lib\site-packages\telegram\ext\_updater.py", line 747, in do_action
    return action_cb_task.result()
           ^^^^^^^^^^^^^^^^^^^^^^^
  File "C:\Users\Стас\AppData\Local\Programs\Python\Python312\Lib\site-packages\telegram\ext\_updater.py", line 377, in polling_action_cb
    updates = await self.bot.get_updates(
              ^^^^^^^^^^^^^^^^^^^^^^^^^^^
  File "C:\Users\Стас\AppData\Local\Programs\Python\Python312\Lib\site-packages\telegram\ext\_extbot.py", line 649, in get_updates
    updates = await super().get_updates(
              ^^^^^^^^^^^^^^^^^^^^^^^^^^
  File "C:\Users\Стас\AppData\Local\Programs\Python\Python312\Lib\site-packages\telegram\_bot.py", line 4366, in get_updates
    await self._post(
  File "C:\Users\Стас\AppData\Local\Programs\Python\Python312\Lib\site-packages\telegram\_bot.py", line 623, in _post
    return await self._do_post(
           ^^^^^^^^^^^^^^^^^^^^
  File "C:\Users\Стас\AppData\Local\Programs\Python\Python312\Lib\site-packages\telegram\ext\_extbot.py", line 355, in _do_post
    return await super()._do_post(
           ^^^^^^^^^^^^^^^^^^^^^^^
  File "C:\Users\Стас\AppData\Local\Programs\Python\Python312\Lib\site-packages\telegram\_bot.py", line 652, in _do_post
    result = await request.post(
             ^^^^^^^^^^^^^^^^^^^
  File "C:\Users\Стас\AppData\Local\Programs\Python\Python312\Lib\site-packages\telegram\request\_baserequest.py", line 201, in post
    result = await self._request_wrapper(
             ^^^^^^^^^^^^^^^^^^^^^^^^^^^^
  File "C:\Users\Стас\AppData\Local\Programs\Python\Python312\Lib\site-packages\telegram\request\_baserequest.py", line 333, in _request_wrapper
    code, payload = await self.do_request(
                    ^^^^^^^^^^^^^^^^^^^^^^
  File "C:\Users\Стас\AppData\Local\Programs\Python\Python312\Lib\site-packages\telegram\request\_httpxrequest.py", line 316, in do_request
    raise NetworkError(f"httpx.{err.__class__.__name__}: {err}") from err
telegram.error.NetworkError: httpx.ConnectError: [Errno 11001] getaddrinfo failed
2024-10-22 15:46:26,637 - httpx - INFO - HTTP Request: POST https://api.telegram.org/bot7388192040:AAE6ySUHROsj21UOZkSxs4uOmdVnRrKTmC4/getUpdates "HTTP/1.1 200 OK"
2024-10-22 15:46:26,641 - __main__ - INFO - Команда /start від користувача 659171286
2024-10-22 15:46:26,644 - __main__ - INFO - Створення нового гаманця для користувача 659171286
2024-10-22 15:46:26,662 - __main__ - INFO - Починаємо шифрування приватного ключа
2024-10-22 15:46:26,678 - __main__ - INFO - Шифрування успішно завершено
2024-10-22 15:46:26,694 - __main__ - INFO - Новий гаманець успішно створено для користувача 659171286
2024-10-22 15:46:28,945 - httpx - INFO - HTTP Request: POST https://api.telegram.org/bot7388192040:AAE6ySUHROsj21UOZkSxs4uOmdVnRrKTmC4/sendMessage "HTTP/1.1 200 OK"
2024-10-22 15:46:32,611 - httpx - INFO - HTTP Request: POST https://api.telegram.org/bot7388192040:AAE6ySUHROsj21UOZkSxs4uOmdVnRrKTmC4/sendMessage "HTTP/1.1 200 OK"
2024-10-22 15:46:38,985 - httpx - INFO - HTTP Request: POST https://api.telegram.org/bot7388192040:AAE6ySUHROsj21UOZkSxs4uOmdVnRrKTmC4/getUpdates "HTTP/1.1 200 OK"
2024-10-22 15:46:53,321 - httpx - INFO - HTTP Request: POST https://api.telegram.org/bot7388192040:AAE6ySUHROsj21UOZkSxs4uOmdVnRrKTmC4/getUpdates "HTTP/1.1 200 OK"
2024-10-22 15:47:04,686 - telegram.ext.Application - ERROR - No error handlers are registered, logging exception.
Traceback (most recent call last):
  File "C:\Users\Стас\AppData\Local\Programs\Python\Python312\Lib\site-packages\httpx\_transports\default.py", line 72, in map_httpcore_exceptions
    yield
  File "C:\Users\Стас\AppData\Local\Programs\Python\Python312\Lib\site-packages\httpx\_transports\default.py", line 377, in handle_async_request
    resp = await self._pool.handle_async_request(req)
           ^^^^^^^^^^^^^^^^^^^^^^^^^^^^^^^^^^^^^^^^^^
  File "C:\Users\Стас\AppData\Local\Programs\Python\Python312\Lib\site-packages\httpcore\_async\connection_pool.py", line 216, in handle_async_request
    raise exc from None
  File "C:\Users\Стас\AppData\Local\Programs\Python\Python312\Lib\site-packages\httpcore\_async\connection_pool.py", line 196, in handle_async_request
    response = await connection.handle_async_request(
               ^^^^^^^^^^^^^^^^^^^^^^^^^^^^^^^^^^^^^^
  File "C:\Users\Стас\AppData\Local\Programs\Python\Python312\Lib\site-packages\httpcore\_async\connection.py", line 101, in handle_async_request
    return await self._connection.handle_async_request(request)
           ^^^^^^^^^^^^^^^^^^^^^^^^^^^^^^^^^^^^^^^^^^^^^^^^^^^^
  File "C:\Users\Стас\AppData\Local\Programs\Python\Python312\Lib\site-packages\httpcore\_async\http11.py", line 143, in handle_async_request
    raise exc
  File "C:\Users\Стас\AppData\Local\Programs\Python\Python312\Lib\site-packages\httpcore\_async\http11.py", line 113, in handle_async_request
    ) = await self._receive_response_headers(**kwargs)
        ^^^^^^^^^^^^^^^^^^^^^^^^^^^^^^^^^^^^^^^^^^^^^^
  File "C:\Users\Стас\AppData\Local\Programs\Python\Python312\Lib\site-packages\httpcore\_async\http11.py", line 186, in _receive_response_headers
    event = await self._receive_event(timeout=timeout)
            ^^^^^^^^^^^^^^^^^^^^^^^^^^^^^^^^^^^^^^^^^^
  File "C:\Users\Стас\AppData\Local\Programs\Python\Python312\Lib\site-packages\httpcore\_async\http11.py", line 224, in _receive_event
    data = await self._network_stream.read(
           ^^^^^^^^^^^^^^^^^^^^^^^^^^^^^^^^
  File "C:\Users\Стас\AppData\Local\Programs\Python\Python312\Lib\site-packages\httpcore\_backends\anyio.py", line 32, in read
    with map_exceptions(exc_map):
  File "C:\Users\Стас\AppData\Local\Programs\Python\Python312\Lib\contextlib.py", line 158, in __exit__
    self.gen.throw(value)
  File "C:\Users\Стас\AppData\Local\Programs\Python\Python312\Lib\site-packages\httpcore\_exceptions.py", line 14, in map_exceptions
    raise to_exc(exc) from exc
httpcore.ReadError

The above exception was the direct cause of the following exception:

Traceback (most recent call last):
  File "C:\Users\Стас\AppData\Local\Programs\Python\Python312\Lib\site-packages\telegram\request\_httpxrequest.py", line 292, in do_request
    res = await self._client.request(
          ^^^^^^^^^^^^^^^^^^^^^^^^^^^
  File "C:\Users\Стас\AppData\Local\Programs\Python\Python312\Lib\site-packages\httpx\_client.py", line 1585, in request
    return await self.send(request, auth=auth, follow_redirects=follow_redirects)
           ^^^^^^^^^^^^^^^^^^^^^^^^^^^^^^^^^^^^^^^^^^^^^^^^^^^^^^^^^^^^^^^^^^^^^^
  File "C:\Users\Стас\AppData\Local\Programs\Python\Python312\Lib\site-packages\httpx\_client.py", line 1674, in send
    response = await self._send_handling_auth(
               ^^^^^^^^^^^^^^^^^^^^^^^^^^^^^^^
  File "C:\Users\Стас\AppData\Local\Programs\Python\Python312\Lib\site-packages\httpx\_client.py", line 1702, in _send_handling_auth
    response = await self._send_handling_redirects(
               ^^^^^^^^^^^^^^^^^^^^^^^^^^^^^^^^^^^^
  File "C:\Users\Стас\AppData\Local\Programs\Python\Python312\Lib\site-packages\httpx\_client.py", line 1739, in _send_handling_redirects
    response = await self._send_single_request(request)
               ^^^^^^^^^^^^^^^^^^^^^^^^^^^^^^^^^^^^^^^^
  File "C:\Users\Стас\AppData\Local\Programs\Python\Python312\Lib\site-packages\httpx\_client.py", line 1776, in _send_single_request
    response = await transport.handle_async_request(request)
               ^^^^^^^^^^^^^^^^^^^^^^^^^^^^^^^^^^^^^^^^^^^^^
  File "C:\Users\Стас\AppData\Local\Programs\Python\Python312\Lib\site-packages\httpx\_transports\default.py", line 376, in handle_async_request
    with map_httpcore_exceptions():
  File "C:\Users\Стас\AppData\Local\Programs\Python\Python312\Lib\contextlib.py", line 158, in __exit__
    self.gen.throw(value)
  File "C:\Users\Стас\AppData\Local\Programs\Python\Python312\Lib\site-packages\httpx\_transports\default.py", line 89, in map_httpcore_exceptions
    raise mapped_exc(message) from exc
httpx.ReadError

The above exception was the direct cause of the following exception:

Traceback (most recent call last):
  File "C:\Users\Стас\AppData\Local\Programs\Python\Python312\Lib\site-packages\telegram\ext\_updater.py", line 753, in _network_loop_retry
    if not await do_action():
           ^^^^^^^^^^^^^^^^^
  File "C:\Users\Стас\AppData\Local\Programs\Python\Python312\Lib\site-packages\telegram\ext\_updater.py", line 747, in do_action
    return action_cb_task.result()
           ^^^^^^^^^^^^^^^^^^^^^^^
  File "C:\Users\Стас\AppData\Local\Programs\Python\Python312\Lib\site-packages\telegram\ext\_updater.py", line 377, in polling_action_cb
    updates = await self.bot.get_updates(
              ^^^^^^^^^^^^^^^^^^^^^^^^^^^
  File "C:\Users\Стас\AppData\Local\Programs\Python\Python312\Lib\site-packages\telegram\ext\_extbot.py", line 649, in get_updates
    updates = await super().get_updates(
              ^^^^^^^^^^^^^^^^^^^^^^^^^^
  File "C:\Users\Стас\AppData\Local\Programs\Python\Python312\Lib\site-packages\telegram\_bot.py", line 4366, in get_updates
    await self._post(
  File "C:\Users\Стас\AppData\Local\Programs\Python\Python312\Lib\site-packages\telegram\_bot.py", line 623, in _post
    return await self._do_post(
           ^^^^^^^^^^^^^^^^^^^^
  File "C:\Users\Стас\AppData\Local\Programs\Python\Python312\Lib\site-packages\telegram\ext\_extbot.py", line 355, in _do_post
    return await super()._do_post(
           ^^^^^^^^^^^^^^^^^^^^^^^
  File "C:\Users\Стас\AppData\Local\Programs\Python\Python312\Lib\site-packages\telegram\_bot.py", line 652, in _do_post
    result = await request.post(
             ^^^^^^^^^^^^^^^^^^^
  File "C:\Users\Стас\AppData\Local\Programs\Python\Python312\Lib\site-packages\telegram\request\_baserequest.py", line 201, in post
    result = await self._request_wrapper(
             ^^^^^^^^^^^^^^^^^^^^^^^^^^^^
  File "C:\Users\Стас\AppData\Local\Programs\Python\Python312\Lib\site-packages\telegram\request\_baserequest.py", line 333, in _request_wrapper
    code, payload = await self.do_request(
                    ^^^^^^^^^^^^^^^^^^^^^^
  File "C:\Users\Стас\AppData\Local\Programs\Python\Python312\Lib\site-packages\telegram\request\_httpxrequest.py", line 316, in do_request
    raise NetworkError(f"httpx.{err.__class__.__name__}: {err}") from err
telegram.error.NetworkError: httpx.ReadError: 
2024-10-22 15:47:06,119 - httpx - INFO - HTTP Request: POST https://api.telegram.org/bot7388192040:AAE6ySUHROsj21UOZkSxs4uOmdVnRrKTmC4/getUpdates "HTTP/1.1 200 OK"
2024-10-22 15:47:06,121 - __main__ - INFO - Отримано натискання кнопки від користувача 867084500: Отримати зашифрований ключ
2024-10-22 15:47:06,125 - __main__ - INFO - Знайдено дані гаманця для користувача 867084500
2024-10-22 15:47:06,126 - __main__ - INFO - Відправляємо зашифрований ключ користувачу 867084500
2024-10-22 15:47:06,718 - httpx - INFO - HTTP Request: POST https://api.telegram.org/bot7388192040:AAE6ySUHROsj21UOZkSxs4uOmdVnRrKTmC4/sendMessage "HTTP/1.1 200 OK"
2024-10-22 15:47:06,721 - __main__ - INFO - Відповідь успішно надіслано користувачу 867084500
2024-10-22 15:47:16,292 - httpx - INFO - HTTP Request: POST https://api.telegram.org/bot7388192040:AAE6ySUHROsj21UOZkSxs4uOmdVnRrKTmC4/getUpdates "HTTP/1.1 200 OK"
2024-10-22 15:47:26,465 - httpx - INFO - HTTP Request: POST https://api.telegram.org/bot7388192040:AAE6ySUHROsj21UOZkSxs4uOmdVnRrKTmC4/getUpdates "HTTP/1.1 200 OK"
2024-10-22 15:47:36,598 - httpx - INFO - HTTP Request: POST https://api.telegram.org/bot7388192040:AAE6ySUHROsj21UOZkSxs4uOmdVnRrKTmC4/getUpdates "HTTP/1.1 200 OK"
2024-10-22 15:47:46,741 - httpx - INFO - HTTP Request: POST https://api.telegram.org/bot7388192040:AAE6ySUHROsj21UOZkSxs4uOmdVnRrKTmC4/getUpdates "HTTP/1.1 200 OK"
2024-10-22 15:47:56,879 - httpx - INFO - HTTP Request: POST https://api.telegram.org/bot7388192040:AAE6ySUHROsj21UOZkSxs4uOmdVnRrKTmC4/getUpdates "HTTP/1.1 200 OK"
2024-10-22 15:48:07,017 - httpx - INFO - HTTP Request: POST https://api.telegram.org/bot7388192040:AAE6ySUHROsj21UOZkSxs4uOmdVnRrKTmC4/getUpdates "HTTP/1.1 200 OK"
2024-10-22 15:48:17,144 - httpx - INFO - HTTP Request: POST https://api.telegram.org/bot7388192040:AAE6ySUHROsj21UOZkSxs4uOmdVnRrKTmC4/getUpdates "HTTP/1.1 200 OK"
2024-10-22 15:48:27,286 - httpx - INFO - HTTP Request: POST https://api.telegram.org/bot7388192040:AAE6ySUHROsj21UOZkSxs4uOmdVnRrKTmC4/getUpdates "HTTP/1.1 200 OK"
2024-10-22 15:48:37,379 - httpx - INFO - HTTP Request: POST https://api.telegram.org/bot7388192040:AAE6ySUHROsj21UOZkSxs4uOmdVnRrKTmC4/getUpdates "HTTP/1.1 200 OK"
2024-10-22 15:48:47,431 - httpx - INFO - HTTP Request: POST https://api.telegram.org/bot7388192040:AAE6ySUHROsj21UOZkSxs4uOmdVnRrKTmC4/getUpdates "HTTP/1.1 200 OK"
2024-10-22 15:48:57,490 - httpx - INFO - HTTP Request: POST https://api.telegram.org/bot7388192040:AAE6ySUHROsj21UOZkSxs4uOmdVnRrKTmC4/getUpdates "HTTP/1.1 200 OK"
2024-10-22 15:49:07,549 - httpx - INFO - HTTP Request: POST https://api.telegram.org/bot7388192040:AAE6ySUHROsj21UOZkSxs4uOmdVnRrKTmC4/getUpdates "HTTP/1.1 200 OK"
2024-10-22 15:49:17,775 - httpx - INFO - HTTP Request: POST https://api.telegram.org/bot7388192040:AAE6ySUHROsj21UOZkSxs4uOmdVnRrKTmC4/getUpdates "HTTP/1.1 200 OK"
2024-10-22 15:49:28,006 - httpx - INFO - HTTP Request: POST https://api.telegram.org/bot7388192040:AAE6ySUHROsj21UOZkSxs4uOmdVnRrKTmC4/getUpdates "HTTP/1.1 200 OK"
2024-10-22 15:49:38,255 - httpx - INFO - HTTP Request: POST https://api.telegram.org/bot7388192040:AAE6ySUHROsj21UOZkSxs4uOmdVnRrKTmC4/getUpdates "HTTP/1.1 200 OK"
2024-10-22 15:49:49,418 - httpx - INFO - HTTP Request: POST https://api.telegram.org/bot7388192040:AAE6ySUHROsj21UOZkSxs4uOmdVnRrKTmC4/getUpdates "HTTP/1.1 200 OK"
2024-10-22 15:49:59,760 - httpx - INFO - HTTP Request: POST https://api.telegram.org/bot7388192040:AAE6ySUHROsj21UOZkSxs4uOmdVnRrKTmC4/getUpdates "HTTP/1.1 200 OK"
2024-10-22 15:50:09,896 - httpx - INFO - HTTP Request: POST https://api.telegram.org/bot7388192040:AAE6ySUHROsj21UOZkSxs4uOmdVnRrKTmC4/getUpdates "HTTP/1.1 200 OK"
2024-10-22 15:50:20,143 - httpx - INFO - HTTP Request: POST https://api.telegram.org/bot7388192040:AAE6ySUHROsj21UOZkSxs4uOmdVnRrKTmC4/getUpdates "HTTP/1.1 200 OK"
2024-10-22 15:50:30,266 - httpx - INFO - HTTP Request: POST https://api.telegram.org/bot7388192040:AAE6ySUHROsj21UOZkSxs4uOmdVnRrKTmC4/getUpdates "HTTP/1.1 200 OK"
2024-10-22 15:50:40,415 - httpx - INFO - HTTP Request: POST https://api.telegram.org/bot7388192040:AAE6ySUHROsj21UOZkSxs4uOmdVnRrKTmC4/getUpdates "HTTP/1.1 200 OK"
2024-10-22 15:50:50,551 - httpx - INFO - HTTP Request: POST https://api.telegram.org/bot7388192040:AAE6ySUHROsj21UOZkSxs4uOmdVnRrKTmC4/getUpdates "HTTP/1.1 200 OK"
2024-10-22 15:51:00,681 - httpx - INFO - HTTP Request: POST https://api.telegram.org/bot7388192040:AAE6ySUHROsj21UOZkSxs4uOmdVnRrKTmC4/getUpdates "HTTP/1.1 200 OK"
2024-10-22 15:51:10,926 - httpx - INFO - HTTP Request: POST https://api.telegram.org/bot7388192040:AAE6ySUHROsj21UOZkSxs4uOmdVnRrKTmC4/getUpdates "HTTP/1.1 200 OK"
2024-10-22 15:51:20,982 - httpx - INFO - HTTP Request: POST https://api.telegram.org/bot7388192040:AAE6ySUHROsj21UOZkSxs4uOmdVnRrKTmC4/getUpdates "HTTP/1.1 200 OK"
2024-10-22 15:51:31,190 - httpx - INFO - HTTP Request: POST https://api.telegram.org/bot7388192040:AAE6ySUHROsj21UOZkSxs4uOmdVnRrKTmC4/getUpdates "HTTP/1.1 200 OK"
2024-10-22 15:51:41,647 - httpx - INFO - HTTP Request: POST https://api.telegram.org/bot7388192040:AAE6ySUHROsj21UOZkSxs4uOmdVnRrKTmC4/getUpdates "HTTP/1.1 200 OK"
2024-10-22 15:51:51,887 - httpx - INFO - HTTP Request: POST https://api.telegram.org/bot7388192040:AAE6ySUHROsj21UOZkSxs4uOmdVnRrKTmC4/getUpdates "HTTP/1.1 200 OK"
2024-10-22 15:52:02,119 - httpx - INFO - HTTP Request: POST https://api.telegram.org/bot7388192040:AAE6ySUHROsj21UOZkSxs4uOmdVnRrKTmC4/getUpdates "HTTP/1.1 200 OK"
2024-10-22 15:52:12,231 - httpx - INFO - HTTP Request: POST https://api.telegram.org/bot7388192040:AAE6ySUHROsj21UOZkSxs4uOmdVnRrKTmC4/getUpdates "HTTP/1.1 200 OK"
2024-10-22 16:09:09,706 - httpx - INFO - HTTP Request: POST https://api.telegram.org/bot7388192040:AAE6ySUHROsj21UOZkSxs4uOmdVnRrKTmC4/getUpdates "HTTP/1.1 200 OK"
2024-10-22 16:09:11,413 - telegram.ext.Application - ERROR - No error handlers are registered, logging exception.
Traceback (most recent call last):
  File "C:\Users\Стас\AppData\Local\Programs\Python\Python312\Lib\site-packages\httpx\_transports\default.py", line 72, in map_httpcore_exceptions
    yield
  File "C:\Users\Стас\AppData\Local\Programs\Python\Python312\Lib\site-packages\httpx\_transports\default.py", line 377, in handle_async_request
    resp = await self._pool.handle_async_request(req)
           ^^^^^^^^^^^^^^^^^^^^^^^^^^^^^^^^^^^^^^^^^^
  File "C:\Users\Стас\AppData\Local\Programs\Python\Python312\Lib\site-packages\httpcore\_async\connection_pool.py", line 216, in handle_async_request
    raise exc from None
  File "C:\Users\Стас\AppData\Local\Programs\Python\Python312\Lib\site-packages\httpcore\_async\connection_pool.py", line 196, in handle_async_request
    response = await connection.handle_async_request(
               ^^^^^^^^^^^^^^^^^^^^^^^^^^^^^^^^^^^^^^
  File "C:\Users\Стас\AppData\Local\Programs\Python\Python312\Lib\site-packages\httpcore\_async\connection.py", line 101, in handle_async_request
    return await self._connection.handle_async_request(request)
           ^^^^^^^^^^^^^^^^^^^^^^^^^^^^^^^^^^^^^^^^^^^^^^^^^^^^
  File "C:\Users\Стас\AppData\Local\Programs\Python\Python312\Lib\site-packages\httpcore\_async\http11.py", line 143, in handle_async_request
    raise exc
  File "C:\Users\Стас\AppData\Local\Programs\Python\Python312\Lib\site-packages\httpcore\_async\http11.py", line 113, in handle_async_request
    ) = await self._receive_response_headers(**kwargs)
        ^^^^^^^^^^^^^^^^^^^^^^^^^^^^^^^^^^^^^^^^^^^^^^
  File "C:\Users\Стас\AppData\Local\Programs\Python\Python312\Lib\site-packages\httpcore\_async\http11.py", line 186, in _receive_response_headers
    event = await self._receive_event(timeout=timeout)
            ^^^^^^^^^^^^^^^^^^^^^^^^^^^^^^^^^^^^^^^^^^
  File "C:\Users\Стас\AppData\Local\Programs\Python\Python312\Lib\site-packages\httpcore\_async\http11.py", line 224, in _receive_event
    data = await self._network_stream.read(
           ^^^^^^^^^^^^^^^^^^^^^^^^^^^^^^^^
  File "C:\Users\Стас\AppData\Local\Programs\Python\Python312\Lib\site-packages\httpcore\_backends\anyio.py", line 32, in read
    with map_exceptions(exc_map):
  File "C:\Users\Стас\AppData\Local\Programs\Python\Python312\Lib\contextlib.py", line 158, in __exit__
    self.gen.throw(value)
  File "C:\Users\Стас\AppData\Local\Programs\Python\Python312\Lib\site-packages\httpcore\_exceptions.py", line 14, in map_exceptions
    raise to_exc(exc) from exc
httpcore.ReadError

The above exception was the direct cause of the following exception:

Traceback (most recent call last):
  File "C:\Users\Стас\AppData\Local\Programs\Python\Python312\Lib\site-packages\telegram\request\_httpxrequest.py", line 292, in do_request
    res = await self._client.request(
          ^^^^^^^^^^^^^^^^^^^^^^^^^^^
  File "C:\Users\Стас\AppData\Local\Programs\Python\Python312\Lib\site-packages\httpx\_client.py", line 1585, in request
    return await self.send(request, auth=auth, follow_redirects=follow_redirects)
           ^^^^^^^^^^^^^^^^^^^^^^^^^^^^^^^^^^^^^^^^^^^^^^^^^^^^^^^^^^^^^^^^^^^^^^
  File "C:\Users\Стас\AppData\Local\Programs\Python\Python312\Lib\site-packages\httpx\_client.py", line 1674, in send
    response = await self._send_handling_auth(
               ^^^^^^^^^^^^^^^^^^^^^^^^^^^^^^^
  File "C:\Users\Стас\AppData\Local\Programs\Python\Python312\Lib\site-packages\httpx\_client.py", line 1702, in _send_handling_auth
    response = await self._send_handling_redirects(
               ^^^^^^^^^^^^^^^^^^^^^^^^^^^^^^^^^^^^
  File "C:\Users\Стас\AppData\Local\Programs\Python\Python312\Lib\site-packages\httpx\_client.py", line 1739, in _send_handling_redirects
    response = await self._send_single_request(request)
               ^^^^^^^^^^^^^^^^^^^^^^^^^^^^^^^^^^^^^^^^
  File "C:\Users\Стас\AppData\Local\Programs\Python\Python312\Lib\site-packages\httpx\_client.py", line 1776, in _send_single_request
    response = await transport.handle_async_request(request)
               ^^^^^^^^^^^^^^^^^^^^^^^^^^^^^^^^^^^^^^^^^^^^^
  File "C:\Users\Стас\AppData\Local\Programs\Python\Python312\Lib\site-packages\httpx\_transports\default.py", line 376, in handle_async_request
    with map_httpcore_exceptions():
  File "C:\Users\Стас\AppData\Local\Programs\Python\Python312\Lib\contextlib.py", line 158, in __exit__
    self.gen.throw(value)
  File "C:\Users\Стас\AppData\Local\Programs\Python\Python312\Lib\site-packages\httpx\_transports\default.py", line 89, in map_httpcore_exceptions
    raise mapped_exc(message) from exc
httpx.ReadError

The above exception was the direct cause of the following exception:

Traceback (most recent call last):
  File "C:\Users\Стас\AppData\Local\Programs\Python\Python312\Lib\site-packages\telegram\ext\_updater.py", line 753, in _network_loop_retry
    if not await do_action():
           ^^^^^^^^^^^^^^^^^
  File "C:\Users\Стас\AppData\Local\Programs\Python\Python312\Lib\site-packages\telegram\ext\_updater.py", line 747, in do_action
    return action_cb_task.result()
           ^^^^^^^^^^^^^^^^^^^^^^^
  File "C:\Users\Стас\AppData\Local\Programs\Python\Python312\Lib\site-packages\telegram\ext\_updater.py", line 377, in polling_action_cb
    updates = await self.bot.get_updates(
              ^^^^^^^^^^^^^^^^^^^^^^^^^^^
  File "C:\Users\Стас\AppData\Local\Programs\Python\Python312\Lib\site-packages\telegram\ext\_extbot.py", line 649, in get_updates
    updates = await super().get_updates(
              ^^^^^^^^^^^^^^^^^^^^^^^^^^
  File "C:\Users\Стас\AppData\Local\Programs\Python\Python312\Lib\site-packages\telegram\_bot.py", line 4366, in get_updates
    await self._post(
  File "C:\Users\Стас\AppData\Local\Programs\Python\Python312\Lib\site-packages\telegram\_bot.py", line 623, in _post
    return await self._do_post(
           ^^^^^^^^^^^^^^^^^^^^
  File "C:\Users\Стас\AppData\Local\Programs\Python\Python312\Lib\site-packages\telegram\ext\_extbot.py", line 355, in _do_post
    return await super()._do_post(
           ^^^^^^^^^^^^^^^^^^^^^^^
  File "C:\Users\Стас\AppData\Local\Programs\Python\Python312\Lib\site-packages\telegram\_bot.py", line 652, in _do_post
    result = await request.post(
             ^^^^^^^^^^^^^^^^^^^
  File "C:\Users\Стас\AppData\Local\Programs\Python\Python312\Lib\site-packages\telegram\request\_baserequest.py", line 201, in post
    result = await self._request_wrapper(
             ^^^^^^^^^^^^^^^^^^^^^^^^^^^^
  File "C:\Users\Стас\AppData\Local\Programs\Python\Python312\Lib\site-packages\telegram\request\_baserequest.py", line 333, in _request_wrapper
    code, payload = await self.do_request(
                    ^^^^^^^^^^^^^^^^^^^^^^
  File "C:\Users\Стас\AppData\Local\Programs\Python\Python312\Lib\site-packages\telegram\request\_httpxrequest.py", line 316, in do_request
    raise NetworkError(f"httpx.{err.__class__.__name__}: {err}") from err
telegram.error.NetworkError: httpx.ReadError: 
2024-10-22 16:09:12,555 - httpx - INFO - HTTP Request: POST https://api.telegram.org/bot7388192040:AAE6ySUHROsj21UOZkSxs4uOmdVnRrKTmC4/getUpdates "HTTP/1.1 200 OK"
2024-10-22 16:09:12,557 - __main__ - INFO - Команда /start від користувача 659171286
2024-10-22 16:09:12,557 - __main__ - INFO - Знайдено існуючий гаманець для користувача 659171286
2024-10-22 16:09:12,709 - httpx - INFO - HTTP Request: POST https://api.telegram.org/bot7388192040:AAE6ySUHROsj21UOZkSxs4uOmdVnRrKTmC4/sendMessage "HTTP/1.1 200 OK"
2024-10-22 16:09:12,717 - __main__ - INFO - Отримано натискання кнопки від користувача 659171286: Отримати розшифрований ключ
2024-10-22 16:09:12,717 - __main__ - INFO - Знайдено дані гаманця для користувача 659171286
2024-10-22 16:09:12,717 - __main__ - INFO - Спроба розшифрування ключа для користувача 659171286
2024-10-22 16:09:12,717 - __main__ - INFO - Починаємо розшифрування приватного ключа
2024-10-22 16:09:12,717 - __main__ - INFO - Розшифрування успішно завершено
2024-10-22 16:09:12,722 - __main__ - INFO - Ключ успішно розшифровано для користувача 659171286
2024-10-22 16:09:12,780 - httpx - INFO - HTTP Request: POST https://api.telegram.org/bot7388192040:AAE6ySUHROsj21UOZkSxs4uOmdVnRrKTmC4/sendMessage "HTTP/1.1 200 OK"
2024-10-22 16:09:12,780 - __main__ - INFO - Відповідь успішно надіслано користувачу 659171286
2024-10-22 16:09:12,780 - __main__ - INFO - Отримано натискання кнопки від користувача 659171286: Отримати зашифрований ключ
2024-10-22 16:09:12,788 - __main__ - INFO - Знайдено дані гаманця для користувача 659171286
2024-10-22 16:09:12,788 - __main__ - INFO - Відправляємо зашифрований ключ користувачу 659171286
2024-10-22 16:09:12,870 - httpx - INFO - HTTP Request: POST https://api.telegram.org/bot7388192040:AAE6ySUHROsj21UOZkSxs4uOmdVnRrKTmC4/sendMessage "HTTP/1.1 200 OK"
2024-10-22 16:09:12,870 - __main__ - INFO - Відповідь успішно надіслано користувачу 659171286
2024-10-22 16:09:12,870 - __main__ - INFO - Команда /start від користувача 659171286
2024-10-22 16:09:12,877 - __main__ - INFO - Знайдено існуючий гаманець для користувача 659171286
2024-10-22 16:09:12,939 - httpx - INFO - HTTP Request: POST https://api.telegram.org/bot7388192040:AAE6ySUHROsj21UOZkSxs4uOmdVnRrKTmC4/sendMessage "HTTP/1.1 200 OK"
2024-10-22 16:09:12,939 - __main__ - INFO - Отримано натискання кнопки від користувача 659171286: Отримати зашифрований ключ
2024-10-22 16:09:12,939 - __main__ - INFO - Знайдено дані гаманця для користувача 659171286
2024-10-22 16:09:12,939 - __main__ - INFO - Відправляємо зашифрований ключ користувачу 659171286
2024-10-22 16:09:13,025 - httpx - INFO - HTTP Request: POST https://api.telegram.org/bot7388192040:AAE6ySUHROsj21UOZkSxs4uOmdVnRrKTmC4/sendMessage "HTTP/1.1 200 OK"
2024-10-22 16:09:13,033 - __main__ - INFO - Відповідь успішно надіслано користувачу 659171286
2024-10-22 16:09:13,033 - __main__ - INFO - Отримано натискання кнопки від користувача 659171286: Отримати розшифрований ключ
2024-10-22 16:09:13,033 - __main__ - INFO - Знайдено дані гаманця для користувача 659171286
2024-10-22 16:09:13,033 - __main__ - INFO - Спроба розшифрування ключа для користувача 659171286
2024-10-22 16:09:13,033 - __main__ - INFO - Починаємо розшифрування приватного ключа
2024-10-22 16:09:13,033 - __main__ - INFO - Розшифрування успішно завершено
2024-10-22 16:09:13,033 - __main__ - INFO - Ключ успішно розшифровано для користувача 659171286
2024-10-22 16:09:13,114 - httpx - INFO - HTTP Request: POST https://api.telegram.org/bot7388192040:AAE6ySUHROsj21UOZkSxs4uOmdVnRrKTmC4/sendMessage "HTTP/1.1 200 OK"
2024-10-22 16:09:13,123 - __main__ - INFO - Відповідь успішно надіслано користувачу 659171286
2024-10-22 17:04:45,090 - telegram.ext.Application - ERROR - No error handlers are registered, logging exception.
Traceback (most recent call last):
  File "C:\Users\Стас\AppData\Local\Programs\Python\Python312\Lib\site-packages\httpx\_transports\default.py", line 72, in map_httpcore_exceptions
    yield
  File "C:\Users\Стас\AppData\Local\Programs\Python\Python312\Lib\site-packages\httpx\_transports\default.py", line 377, in handle_async_request
    resp = await self._pool.handle_async_request(req)
           ^^^^^^^^^^^^^^^^^^^^^^^^^^^^^^^^^^^^^^^^^^
  File "C:\Users\Стас\AppData\Local\Programs\Python\Python312\Lib\site-packages\httpcore\_async\connection_pool.py", line 216, in handle_async_request
    raise exc from None
  File "C:\Users\Стас\AppData\Local\Programs\Python\Python312\Lib\site-packages\httpcore\_async\connection_pool.py", line 196, in handle_async_request
    response = await connection.handle_async_request(
               ^^^^^^^^^^^^^^^^^^^^^^^^^^^^^^^^^^^^^^
  File "C:\Users\Стас\AppData\Local\Programs\Python\Python312\Lib\site-packages\httpcore\_async\connection.py", line 99, in handle_async_request
    raise exc
  File "C:\Users\Стас\AppData\Local\Programs\Python\Python312\Lib\site-packages\httpcore\_async\connection.py", line 76, in handle_async_request
    stream = await self._connect(request)
             ^^^^^^^^^^^^^^^^^^^^^^^^^^^^
  File "C:\Users\Стас\AppData\Local\Programs\Python\Python312\Lib\site-packages\httpcore\_async\connection.py", line 122, in _connect
    stream = await self._network_backend.connect_tcp(**kwargs)
             ^^^^^^^^^^^^^^^^^^^^^^^^^^^^^^^^^^^^^^^^^^^^^^^^^
  File "C:\Users\Стас\AppData\Local\Programs\Python\Python312\Lib\site-packages\httpcore\_backends\auto.py", line 30, in connect_tcp
    return await self._backend.connect_tcp(
           ^^^^^^^^^^^^^^^^^^^^^^^^^^^^^^^^
  File "C:\Users\Стас\AppData\Local\Programs\Python\Python312\Lib\site-packages\httpcore\_backends\anyio.py", line 115, in connect_tcp
    with map_exceptions(exc_map):
  File "C:\Users\Стас\AppData\Local\Programs\Python\Python312\Lib\contextlib.py", line 158, in __exit__
    self.gen.throw(value)
  File "C:\Users\Стас\AppData\Local\Programs\Python\Python312\Lib\site-packages\httpcore\_exceptions.py", line 14, in map_exceptions
    raise to_exc(exc) from exc
httpcore.ConnectError: [Errno 11001] getaddrinfo failed

The above exception was the direct cause of the following exception:

Traceback (most recent call last):
  File "C:\Users\Стас\AppData\Local\Programs\Python\Python312\Lib\site-packages\telegram\request\_httpxrequest.py", line 292, in do_request
    res = await self._client.request(
          ^^^^^^^^^^^^^^^^^^^^^^^^^^^
  File "C:\Users\Стас\AppData\Local\Programs\Python\Python312\Lib\site-packages\httpx\_client.py", line 1585, in request
    return await self.send(request, auth=auth, follow_redirects=follow_redirects)
           ^^^^^^^^^^^^^^^^^^^^^^^^^^^^^^^^^^^^^^^^^^^^^^^^^^^^^^^^^^^^^^^^^^^^^^
  File "C:\Users\Стас\AppData\Local\Programs\Python\Python312\Lib\site-packages\httpx\_client.py", line 1674, in send
    response = await self._send_handling_auth(
               ^^^^^^^^^^^^^^^^^^^^^^^^^^^^^^^
  File "C:\Users\Стас\AppData\Local\Programs\Python\Python312\Lib\site-packages\httpx\_client.py", line 1702, in _send_handling_auth
    response = await self._send_handling_redirects(
               ^^^^^^^^^^^^^^^^^^^^^^^^^^^^^^^^^^^^
  File "C:\Users\Стас\AppData\Local\Programs\Python\Python312\Lib\site-packages\httpx\_client.py", line 1739, in _send_handling_redirects
    response = await self._send_single_request(request)
               ^^^^^^^^^^^^^^^^^^^^^^^^^^^^^^^^^^^^^^^^
  File "C:\Users\Стас\AppData\Local\Programs\Python\Python312\Lib\site-packages\httpx\_client.py", line 1776, in _send_single_request
    response = await transport.handle_async_request(request)
               ^^^^^^^^^^^^^^^^^^^^^^^^^^^^^^^^^^^^^^^^^^^^^
  File "C:\Users\Стас\AppData\Local\Programs\Python\Python312\Lib\site-packages\httpx\_transports\default.py", line 376, in handle_async_request
    with map_httpcore_exceptions():
  File "C:\Users\Стас\AppData\Local\Programs\Python\Python312\Lib\contextlib.py", line 158, in __exit__
    self.gen.throw(value)
  File "C:\Users\Стас\AppData\Local\Programs\Python\Python312\Lib\site-packages\httpx\_transports\default.py", line 89, in map_httpcore_exceptions
    raise mapped_exc(message) from exc
httpx.ConnectError: [Errno 11001] getaddrinfo failed

The above exception was the direct cause of the following exception:

Traceback (most recent call last):
  File "C:\Users\Стас\AppData\Local\Programs\Python\Python312\Lib\site-packages\telegram\ext\_updater.py", line 753, in _network_loop_retry
    if not await do_action():
           ^^^^^^^^^^^^^^^^^
  File "C:\Users\Стас\AppData\Local\Programs\Python\Python312\Lib\site-packages\telegram\ext\_updater.py", line 747, in do_action
    return action_cb_task.result()
           ^^^^^^^^^^^^^^^^^^^^^^^
  File "C:\Users\Стас\AppData\Local\Programs\Python\Python312\Lib\site-packages\telegram\ext\_updater.py", line 377, in polling_action_cb
    updates = await self.bot.get_updates(
              ^^^^^^^^^^^^^^^^^^^^^^^^^^^
  File "C:\Users\Стас\AppData\Local\Programs\Python\Python312\Lib\site-packages\telegram\ext\_extbot.py", line 649, in get_updates
    updates = await super().get_updates(
              ^^^^^^^^^^^^^^^^^^^^^^^^^^
  File "C:\Users\Стас\AppData\Local\Programs\Python\Python312\Lib\site-packages\telegram\_bot.py", line 4366, in get_updates
    await self._post(
  File "C:\Users\Стас\AppData\Local\Programs\Python\Python312\Lib\site-packages\telegram\_bot.py", line 623, in _post
    return await self._do_post(
           ^^^^^^^^^^^^^^^^^^^^
  File "C:\Users\Стас\AppData\Local\Programs\Python\Python312\Lib\site-packages\telegram\ext\_extbot.py", line 355, in _do_post
    return await super()._do_post(
           ^^^^^^^^^^^^^^^^^^^^^^^
  File "C:\Users\Стас\AppData\Local\Programs\Python\Python312\Lib\site-packages\telegram\_bot.py", line 652, in _do_post
    result = await request.post(
             ^^^^^^^^^^^^^^^^^^^
  File "C:\Users\Стас\AppData\Local\Programs\Python\Python312\Lib\site-packages\telegram\request\_baserequest.py", line 201, in post
    result = await self._request_wrapper(
             ^^^^^^^^^^^^^^^^^^^^^^^^^^^^
  File "C:\Users\Стас\AppData\Local\Programs\Python\Python312\Lib\site-packages\telegram\request\_baserequest.py", line 333, in _request_wrapper
    code, payload = await self.do_request(
                    ^^^^^^^^^^^^^^^^^^^^^^
  File "C:\Users\Стас\AppData\Local\Programs\Python\Python312\Lib\site-packages\telegram\request\_httpxrequest.py", line 316, in do_request
    raise NetworkError(f"httpx.{err.__class__.__name__}: {err}") from err
telegram.error.NetworkError: httpx.ConnectError: [Errno 11001] getaddrinfo failed
2024-10-22 17:04:46,100 - telegram.ext.Application - ERROR - No error handlers are registered, logging exception.
Traceback (most recent call last):
  File "C:\Users\Стас\AppData\Local\Programs\Python\Python312\Lib\site-packages\httpx\_transports\default.py", line 72, in map_httpcore_exceptions
    yield
  File "C:\Users\Стас\AppData\Local\Programs\Python\Python312\Lib\site-packages\httpx\_transports\default.py", line 377, in handle_async_request
    resp = await self._pool.handle_async_request(req)
           ^^^^^^^^^^^^^^^^^^^^^^^^^^^^^^^^^^^^^^^^^^
  File "C:\Users\Стас\AppData\Local\Programs\Python\Python312\Lib\site-packages\httpcore\_async\connection_pool.py", line 216, in handle_async_request
    raise exc from None
  File "C:\Users\Стас\AppData\Local\Programs\Python\Python312\Lib\site-packages\httpcore\_async\connection_pool.py", line 196, in handle_async_request
    response = await connection.handle_async_request(
               ^^^^^^^^^^^^^^^^^^^^^^^^^^^^^^^^^^^^^^
  File "C:\Users\Стас\AppData\Local\Programs\Python\Python312\Lib\site-packages\httpcore\_async\connection.py", line 99, in handle_async_request
    raise exc
  File "C:\Users\Стас\AppData\Local\Programs\Python\Python312\Lib\site-packages\httpcore\_async\connection.py", line 76, in handle_async_request
    stream = await self._connect(request)
             ^^^^^^^^^^^^^^^^^^^^^^^^^^^^
  File "C:\Users\Стас\AppData\Local\Programs\Python\Python312\Lib\site-packages\httpcore\_async\connection.py", line 122, in _connect
    stream = await self._network_backend.connect_tcp(**kwargs)
             ^^^^^^^^^^^^^^^^^^^^^^^^^^^^^^^^^^^^^^^^^^^^^^^^^
  File "C:\Users\Стас\AppData\Local\Programs\Python\Python312\Lib\site-packages\httpcore\_backends\auto.py", line 30, in connect_tcp
    return await self._backend.connect_tcp(
           ^^^^^^^^^^^^^^^^^^^^^^^^^^^^^^^^
  File "C:\Users\Стас\AppData\Local\Programs\Python\Python312\Lib\site-packages\httpcore\_backends\anyio.py", line 115, in connect_tcp
    with map_exceptions(exc_map):
  File "C:\Users\Стас\AppData\Local\Programs\Python\Python312\Lib\contextlib.py", line 158, in __exit__
    self.gen.throw(value)
  File "C:\Users\Стас\AppData\Local\Programs\Python\Python312\Lib\site-packages\httpcore\_exceptions.py", line 14, in map_exceptions
    raise to_exc(exc) from exc
httpcore.ConnectError: [Errno 11001] getaddrinfo failed

The above exception was the direct cause of the following exception:

Traceback (most recent call last):
  File "C:\Users\Стас\AppData\Local\Programs\Python\Python312\Lib\site-packages\telegram\request\_httpxrequest.py", line 292, in do_request
    res = await self._client.request(
          ^^^^^^^^^^^^^^^^^^^^^^^^^^^
  File "C:\Users\Стас\AppData\Local\Programs\Python\Python312\Lib\site-packages\httpx\_client.py", line 1585, in request
    return await self.send(request, auth=auth, follow_redirects=follow_redirects)
           ^^^^^^^^^^^^^^^^^^^^^^^^^^^^^^^^^^^^^^^^^^^^^^^^^^^^^^^^^^^^^^^^^^^^^^
  File "C:\Users\Стас\AppData\Local\Programs\Python\Python312\Lib\site-packages\httpx\_client.py", line 1674, in send
    response = await self._send_handling_auth(
               ^^^^^^^^^^^^^^^^^^^^^^^^^^^^^^^
  File "C:\Users\Стас\AppData\Local\Programs\Python\Python312\Lib\site-packages\httpx\_client.py", line 1702, in _send_handling_auth
    response = await self._send_handling_redirects(
               ^^^^^^^^^^^^^^^^^^^^^^^^^^^^^^^^^^^^
  File "C:\Users\Стас\AppData\Local\Programs\Python\Python312\Lib\site-packages\httpx\_client.py", line 1739, in _send_handling_redirects
    response = await self._send_single_request(request)
               ^^^^^^^^^^^^^^^^^^^^^^^^^^^^^^^^^^^^^^^^
  File "C:\Users\Стас\AppData\Local\Programs\Python\Python312\Lib\site-packages\httpx\_client.py", line 1776, in _send_single_request
    response = await transport.handle_async_request(request)
               ^^^^^^^^^^^^^^^^^^^^^^^^^^^^^^^^^^^^^^^^^^^^^
  File "C:\Users\Стас\AppData\Local\Programs\Python\Python312\Lib\site-packages\httpx\_transports\default.py", line 376, in handle_async_request
    with map_httpcore_exceptions():
  File "C:\Users\Стас\AppData\Local\Programs\Python\Python312\Lib\contextlib.py", line 158, in __exit__
    self.gen.throw(value)
  File "C:\Users\Стас\AppData\Local\Programs\Python\Python312\Lib\site-packages\httpx\_transports\default.py", line 89, in map_httpcore_exceptions
    raise mapped_exc(message) from exc
httpx.ConnectError: [Errno 11001] getaddrinfo failed

The above exception was the direct cause of the following exception:

Traceback (most recent call last):
  File "C:\Users\Стас\AppData\Local\Programs\Python\Python312\Lib\site-packages\telegram\ext\_updater.py", line 753, in _network_loop_retry
    if not await do_action():
           ^^^^^^^^^^^^^^^^^
  File "C:\Users\Стас\AppData\Local\Programs\Python\Python312\Lib\site-packages\telegram\ext\_updater.py", line 747, in do_action
    return action_cb_task.result()
           ^^^^^^^^^^^^^^^^^^^^^^^
  File "C:\Users\Стас\AppData\Local\Programs\Python\Python312\Lib\site-packages\telegram\ext\_updater.py", line 377, in polling_action_cb
    updates = await self.bot.get_updates(
              ^^^^^^^^^^^^^^^^^^^^^^^^^^^
  File "C:\Users\Стас\AppData\Local\Programs\Python\Python312\Lib\site-packages\telegram\ext\_extbot.py", line 649, in get_updates
    updates = await super().get_updates(
              ^^^^^^^^^^^^^^^^^^^^^^^^^^
  File "C:\Users\Стас\AppData\Local\Programs\Python\Python312\Lib\site-packages\telegram\_bot.py", line 4366, in get_updates
    await self._post(
  File "C:\Users\Стас\AppData\Local\Programs\Python\Python312\Lib\site-packages\telegram\_bot.py", line 623, in _post
    return await self._do_post(
           ^^^^^^^^^^^^^^^^^^^^
  File "C:\Users\Стас\AppData\Local\Programs\Python\Python312\Lib\site-packages\telegram\ext\_extbot.py", line 355, in _do_post
    return await super()._do_post(
           ^^^^^^^^^^^^^^^^^^^^^^^
  File "C:\Users\Стас\AppData\Local\Programs\Python\Python312\Lib\site-packages\telegram\_bot.py", line 652, in _do_post
    result = await request.post(
             ^^^^^^^^^^^^^^^^^^^
  File "C:\Users\Стас\AppData\Local\Programs\Python\Python312\Lib\site-packages\telegram\request\_baserequest.py", line 201, in post
    result = await self._request_wrapper(
             ^^^^^^^^^^^^^^^^^^^^^^^^^^^^
  File "C:\Users\Стас\AppData\Local\Programs\Python\Python312\Lib\site-packages\telegram\request\_baserequest.py", line 333, in _request_wrapper
    code, payload = await self.do_request(
                    ^^^^^^^^^^^^^^^^^^^^^^
  File "C:\Users\Стас\AppData\Local\Programs\Python\Python312\Lib\site-packages\telegram\request\_httpxrequest.py", line 316, in do_request
    raise NetworkError(f"httpx.{err.__class__.__name__}: {err}") from err
telegram.error.NetworkError: httpx.ConnectError: [Errno 11001] getaddrinfo failed
2024-10-22 17:04:47,875 - httpx - INFO - HTTP Request: POST https://api.telegram.org/bot7388192040:AAE6ySUHROsj21UOZkSxs4uOmdVnRrKTmC4/getUpdates "HTTP/1.1 200 OK"
2024-10-22 17:04:47,882 - __main__ - INFO - Отримано натискання кнопки від користувача 659171286: Отримати зашифрований ключ
2024-10-22 17:04:47,888 - __main__ - INFO - Знайдено дані гаманця для користувача 659171286
2024-10-22 17:04:47,888 - __main__ - INFO - Відправляємо зашифрований ключ користувачу 659171286
2024-10-22 17:04:48,093 - httpx - INFO - HTTP Request: POST https://api.telegram.org/bot7388192040:AAE6ySUHROsj21UOZkSxs4uOmdVnRrKTmC4/sendMessage "HTTP/1.1 200 OK"
2024-10-22 17:04:48,097 - __main__ - INFO - Відповідь успішно надіслано користувачу 659171286
2024-10-22 17:04:48,098 - __main__ - INFO - Отримано натискання кнопки від користувача 659171286: Отримати розшифрований ключ
2024-10-22 17:04:48,100 - __main__ - INFO - Знайдено дані гаманця для користувача 659171286
2024-10-22 17:04:48,100 - __main__ - INFO - Спроба розшифрування ключа для користувача 659171286
2024-10-22 17:04:48,102 - __main__ - INFO - Починаємо розшифрування приватного ключа
2024-10-22 17:04:48,103 - __main__ - INFO - Розшифрування успішно завершено
2024-10-22 17:04:48,104 - __main__ - INFO - Ключ успішно розшифровано для користувача 659171286
2024-10-22 17:04:48,546 - httpx - INFO - HTTP Request: POST https://api.telegram.org/bot7388192040:AAE6ySUHROsj21UOZkSxs4uOmdVnRrKTmC4/sendMessage "HTTP/1.1 200 OK"
2024-10-22 17:04:48,549 - __main__ - INFO - Відповідь успішно надіслано користувачу 659171286
2024-10-22 17:04:48,793 - httpx - INFO - HTTP Request: POST https://api.telegram.org/bot7388192040:AAE6ySUHROsj21UOZkSxs4uOmdVnRrKTmC4/sendMessage "HTTP/1.1 200 OK"
2024-10-22 17:04:48,794 - __main__ - INFO - Отримано натискання кнопки від користувача 659171286: Отримати зашифрований ключ
2024-10-22 17:04:48,795 - __main__ - INFO - Знайдено дані гаманця для користувача 659171286
2024-10-22 17:04:48,796 - __main__ - INFO - Відправляємо зашифрований ключ користувачу 659171286
2024-10-22 17:04:49,281 - httpx - INFO - HTTP Request: POST https://api.telegram.org/bot7388192040:AAE6ySUHROsj21UOZkSxs4uOmdVnRrKTmC4/sendMessage "HTTP/1.1 200 OK"
2024-10-22 17:04:49,282 - __main__ - INFO - Відповідь успішно надіслано користувачу 659171286
2024-10-22 23:04:37,964 - __main__ - INFO - Fernet успішно ініціалізовано
2024-10-22 23:04:37,986 - __main__ - INFO - База даних успішно ініціалізована
2024-10-22 23:04:37,986 - __main__ - INFO - Starting the bot
2024-10-22 23:04:38,486 - __main__ - INFO - Handlers added, starting polling
2024-10-22 23:04:38,879 - httpx - INFO - HTTP Request: POST https://api.telegram.org/bot7388192040:AAE6ySUHROsj21UOZkSxs4uOmdVnRrKTmC4/getMe "HTTP/1.1 200 OK"
2024-10-22 23:04:39,079 - httpx - INFO - HTTP Request: POST https://api.telegram.org/bot7388192040:AAE6ySUHROsj21UOZkSxs4uOmdVnRrKTmC4/deleteWebhook "HTTP/1.1 200 OK"
2024-10-22 23:04:39,079 - telegram.ext.Application - INFO - Application started
2024-10-22 23:04:39,594 - httpx - INFO - HTTP Request: POST https://api.telegram.org/bot7388192040:AAE6ySUHROsj21UOZkSxs4uOmdVnRrKTmC4/getUpdates "HTTP/1.1 200 OK"
2024-10-22 23:04:39,594 - __main__ - INFO - Отримано натискання кнопки від користувача 659171286: Отримати зашифрований ключ
2024-10-22 23:04:39,610 - __main__ - INFO - Знайдено дані гаманця для користувача 659171286
2024-10-22 23:04:39,610 - __main__ - INFO - Відправляємо зашифрований ключ користувачу 659171286
2024-10-22 23:04:39,789 - httpx - INFO - HTTP Request: POST https://api.telegram.org/bot7388192040:AAE6ySUHROsj21UOZkSxs4uOmdVnRrKTmC4/sendMessage "HTTP/1.1 200 OK"
2024-10-22 23:04:39,789 - __main__ - INFO - Відповідь успішно надіслано користувачу 659171286
2024-10-22 23:04:49,941 - httpx - INFO - HTTP Request: POST https://api.telegram.org/bot7388192040:AAE6ySUHROsj21UOZkSxs4uOmdVnRrKTmC4/getUpdates "HTTP/1.1 200 OK"
2024-10-22 23:04:57,919 - httpx - INFO - HTTP Request: POST https://api.telegram.org/bot7388192040:AAE6ySUHROsj21UOZkSxs4uOmdVnRrKTmC4/getUpdates "HTTP/1.1 200 OK"
2024-10-22 23:04:57,921 - __main__ - INFO - Отримано натискання кнопки від користувача 867084500: Отримати зашифрований ключ
2024-10-22 23:04:57,924 - __main__ - INFO - Знайдено дані гаманця для користувача 867084500
2024-10-22 23:04:57,924 - __main__ - INFO - Відправляємо зашифрований ключ користувачу 867084500
2024-10-22 23:04:59,158 - httpx - INFO - HTTP Request: POST https://api.telegram.org/bot7388192040:AAE6ySUHROsj21UOZkSxs4uOmdVnRrKTmC4/sendMessage "HTTP/1.1 200 OK"
2024-10-22 23:04:59,161 - __main__ - INFO - Відповідь успішно надіслано користувачу 867084500
2024-10-22 23:05:02,224 - httpx - INFO - HTTP Request: POST https://api.telegram.org/bot7388192040:AAE6ySUHROsj21UOZkSxs4uOmdVnRrKTmC4/getUpdates "HTTP/1.1 200 OK"
2024-10-22 23:05:02,224 - __main__ - INFO - Отримано натискання кнопки від користувача 867084500: Отримати розшифрований ключ
2024-10-22 23:05:02,224 - __main__ - INFO - Знайдено дані гаманця для користувача 867084500
2024-10-22 23:05:02,224 - __main__ - INFO - Спроба розшифрування ключа для користувача 867084500
2024-10-22 23:05:02,224 - __main__ - INFO - Ключ успішно розшифровано для користувача 867084500
2024-10-22 23:05:03,397 - httpx - INFO - HTTP Request: POST https://api.telegram.org/bot7388192040:AAE6ySUHROsj21UOZkSxs4uOmdVnRrKTmC4/sendMessage "HTTP/1.1 200 OK"
2024-10-22 23:05:03,398 - __main__ - INFO - Відповідь успішно надіслано користувачу 867084500
2024-10-22 23:05:13,374 - httpx - INFO - HTTP Request: POST https://api.telegram.org/bot7388192040:AAE6ySUHROsj21UOZkSxs4uOmdVnRrKTmC4/getUpdates "HTTP/1.1 200 OK"
2024-10-22 23:05:24,031 - httpx - INFO - HTTP Request: POST https://api.telegram.org/bot7388192040:AAE6ySUHROsj21UOZkSxs4uOmdVnRrKTmC4/getUpdates "HTTP/1.1 200 OK"
2024-10-22 23:05:34,271 - httpx - INFO - HTTP Request: POST https://api.telegram.org/bot7388192040:AAE6ySUHROsj21UOZkSxs4uOmdVnRrKTmC4/getUpdates "HTTP/1.1 200 OK"
2024-10-22 23:05:44,382 - httpx - INFO - HTTP Request: POST https://api.telegram.org/bot7388192040:AAE6ySUHROsj21UOZkSxs4uOmdVnRrKTmC4/getUpdates "HTTP/1.1 200 OK"
2024-10-22 23:05:56,386 - httpx - INFO - HTTP Request: POST https://api.telegram.org/bot7388192040:AAE6ySUHROsj21UOZkSxs4uOmdVnRrKTmC4/getUpdates "HTTP/1.1 200 OK"
2024-10-22 23:06:06,524 - httpx - INFO - HTTP Request: POST https://api.telegram.org/bot7388192040:AAE6ySUHROsj21UOZkSxs4uOmdVnRrKTmC4/getUpdates "HTTP/1.1 200 OK"
2024-10-22 23:06:16,925 - httpx - INFO - HTTP Request: POST https://api.telegram.org/bot7388192040:AAE6ySUHROsj21UOZkSxs4uOmdVnRrKTmC4/getUpdates "HTTP/1.1 200 OK"
2024-10-22 23:06:27,114 - httpx - INFO - HTTP Request: POST https://api.telegram.org/bot7388192040:AAE6ySUHROsj21UOZkSxs4uOmdVnRrKTmC4/getUpdates "HTTP/1.1 200 OK"
2024-10-22 23:06:38,065 - httpx - INFO - HTTP Request: POST https://api.telegram.org/bot7388192040:AAE6ySUHROsj21UOZkSxs4uOmdVnRrKTmC4/getUpdates "HTTP/1.1 200 OK"
2024-10-22 23:06:49,219 - httpx - INFO - HTTP Request: POST https://api.telegram.org/bot7388192040:AAE6ySUHROsj21UOZkSxs4uOmdVnRrKTmC4/getUpdates "HTTP/1.1 200 OK"
2024-10-22 23:06:59,188 - __main__ - INFO - Fernet успішно ініціалізовано
2024-10-22 23:06:59,188 - __main__ - INFO - База даних успішно ініціалізована
2024-10-22 23:06:59,188 - __main__ - INFO - Starting the bot
2024-10-22 23:06:59,682 - __main__ - INFO - Handlers added, starting polling
2024-10-22 23:07:00,481 - httpx - INFO - HTTP Request: POST https://api.telegram.org/bot7388192040:AAE6ySUHROsj21UOZkSxs4uOmdVnRrKTmC4/getMe "HTTP/1.1 200 OK"
2024-10-22 23:07:00,800 - httpx - INFO - HTTP Request: POST https://api.telegram.org/bot7388192040:AAE6ySUHROsj21UOZkSxs4uOmdVnRrKTmC4/deleteWebhook "HTTP/1.1 200 OK"
2024-10-22 23:07:00,816 - telegram.ext.Application - INFO - Application started
2024-10-22 23:07:08,588 - httpx - INFO - HTTP Request: POST https://api.telegram.org/bot7388192040:AAE6ySUHROsj21UOZkSxs4uOmdVnRrKTmC4/getUpdates "HTTP/1.1 200 OK"
2024-10-22 23:07:08,596 - __main__ - INFO - Отримано натискання кнопки від користувача 867084500: Отримати зашифрований ключ
2024-10-22 23:07:08,596 - __main__ - INFO - Знайдено дані гаманця для користувача 867084500
2024-10-22 23:07:08,596 - __main__ - INFO - Відправляємо зашифрований ключ користувачу 867084500
2024-10-22 23:07:11,252 - httpx - INFO - HTTP Request: POST https://api.telegram.org/bot7388192040:AAE6ySUHROsj21UOZkSxs4uOmdVnRrKTmC4/sendMessage "HTTP/1.1 200 OK"
2024-10-22 23:07:11,257 - __main__ - INFO - Відповідь успішно надіслано користувачу 867084500
2024-10-22 23:07:15,043 - httpx - INFO - HTTP Request: POST https://api.telegram.org/bot7388192040:AAE6ySUHROsj21UOZkSxs4uOmdVnRrKTmC4/getUpdates "HTTP/1.1 200 OK"
2024-10-22 23:07:15,050 - __main__ - INFO - Отримано натискання кнопки від користувача 867084500: Отримати розшифрований ключ
2024-10-22 23:07:15,050 - __main__ - INFO - Знайдено дані гаманця для користувача 867084500
2024-10-22 23:07:15,050 - __main__ - INFO - Спроба розшифрування ключа для користувача 867084500
2024-10-22 23:07:15,050 - __main__ - INFO - Ключ успішно розшифровано для користувача 867084500
2024-10-22 23:07:15,343 - httpx - INFO - HTTP Request: POST https://api.telegram.org/bot7388192040:AAE6ySUHROsj21UOZkSxs4uOmdVnRrKTmC4/sendMessage "HTTP/1.1 200 OK"
2024-10-22 23:07:15,350 - __main__ - INFO - Відповідь успішно надіслано користувачу 867084500
2024-10-22 23:07:25,273 - httpx - INFO - HTTP Request: POST https://api.telegram.org/bot7388192040:AAE6ySUHROsj21UOZkSxs4uOmdVnRrKTmC4/getUpdates "HTTP/1.1 200 OK"
2024-10-22 23:07:35,521 - httpx - INFO - HTTP Request: POST https://api.telegram.org/bot7388192040:AAE6ySUHROsj21UOZkSxs4uOmdVnRrKTmC4/getUpdates "HTTP/1.1 200 OK"
2024-10-22 23:07:46,594 - httpx - INFO - HTTP Request: POST https://api.telegram.org/bot7388192040:AAE6ySUHROsj21UOZkSxs4uOmdVnRrKTmC4/getUpdates "HTTP/1.1 200 OK"
2024-10-22 23:07:56,818 - httpx - INFO - HTTP Request: POST https://api.telegram.org/bot7388192040:AAE6ySUHROsj21UOZkSxs4uOmdVnRrKTmC4/getUpdates "HTTP/1.1 200 OK"
2024-10-22 23:08:06,952 - httpx - INFO - HTTP Request: POST https://api.telegram.org/bot7388192040:AAE6ySUHROsj21UOZkSxs4uOmdVnRrKTmC4/getUpdates "HTTP/1.1 200 OK"
2024-10-22 23:08:17,404 - httpx - INFO - HTTP Request: POST https://api.telegram.org/bot7388192040:AAE6ySUHROsj21UOZkSxs4uOmdVnRrKTmC4/getUpdates "HTTP/1.1 200 OK"
2024-10-22 23:08:28,343 - httpx - INFO - HTTP Request: POST https://api.telegram.org/bot7388192040:AAE6ySUHROsj21UOZkSxs4uOmdVnRrKTmC4/getUpdates "HTTP/1.1 200 OK"
2024-10-22 23:08:38,487 - httpx - INFO - HTTP Request: POST https://api.telegram.org/bot7388192040:AAE6ySUHROsj21UOZkSxs4uOmdVnRrKTmC4/getUpdates "HTTP/1.1 200 OK"
2024-10-22 23:08:49,155 - httpx - INFO - HTTP Request: POST https://api.telegram.org/bot7388192040:AAE6ySUHROsj21UOZkSxs4uOmdVnRrKTmC4/getUpdates "HTTP/1.1 200 OK"
2024-10-22 23:08:59,748 - httpx - INFO - HTTP Request: POST https://api.telegram.org/bot7388192040:AAE6ySUHROsj21UOZkSxs4uOmdVnRrKTmC4/getUpdates "HTTP/1.1 200 OK"
2024-10-22 23:09:10,141 - httpx - INFO - HTTP Request: POST https://api.telegram.org/bot7388192040:AAE6ySUHROsj21UOZkSxs4uOmdVnRrKTmC4/getUpdates "HTTP/1.1 200 OK"
2024-10-22 23:09:20,687 - httpx - INFO - HTTP Request: POST https://api.telegram.org/bot7388192040:AAE6ySUHROsj21UOZkSxs4uOmdVnRrKTmC4/getUpdates "HTTP/1.1 200 OK"
2024-10-22 23:09:30,927 - httpx - INFO - HTTP Request: POST https://api.telegram.org/bot7388192040:AAE6ySUHROsj21UOZkSxs4uOmdVnRrKTmC4/getUpdates "HTTP/1.1 200 OK"
2024-10-22 23:09:41,591 - httpx - INFO - HTTP Request: POST https://api.telegram.org/bot7388192040:AAE6ySUHROsj21UOZkSxs4uOmdVnRrKTmC4/getUpdates "HTTP/1.1 200 OK"
2024-10-22 23:09:52,234 - httpx - INFO - HTTP Request: POST https://api.telegram.org/bot7388192040:AAE6ySUHROsj21UOZkSxs4uOmdVnRrKTmC4/getUpdates "HTTP/1.1 200 OK"
2024-10-22 23:10:02,457 - httpx - INFO - HTTP Request: POST https://api.telegram.org/bot7388192040:AAE6ySUHROsj21UOZkSxs4uOmdVnRrKTmC4/getUpdates "HTTP/1.1 200 OK"
2024-10-22 23:10:12,602 - httpx - INFO - HTTP Request: POST https://api.telegram.org/bot7388192040:AAE6ySUHROsj21UOZkSxs4uOmdVnRrKTmC4/getUpdates "HTTP/1.1 200 OK"
2024-10-22 23:10:23,200 - httpx - INFO - HTTP Request: POST https://api.telegram.org/bot7388192040:AAE6ySUHROsj21UOZkSxs4uOmdVnRrKTmC4/getUpdates "HTTP/1.1 200 OK"
2024-10-22 23:10:33,282 - httpx - INFO - HTTP Request: POST https://api.telegram.org/bot7388192040:AAE6ySUHROsj21UOZkSxs4uOmdVnRrKTmC4/getUpdates "HTTP/1.1 200 OK"
2024-10-22 23:10:43,615 - httpx - INFO - HTTP Request: POST https://api.telegram.org/bot7388192040:AAE6ySUHROsj21UOZkSxs4uOmdVnRrKTmC4/getUpdates "HTTP/1.1 200 OK"
2024-10-22 23:10:54,175 - httpx - INFO - HTTP Request: POST https://api.telegram.org/bot7388192040:AAE6ySUHROsj21UOZkSxs4uOmdVnRrKTmC4/getUpdates "HTTP/1.1 200 OK"
2024-10-22 23:11:04,406 - httpx - INFO - HTTP Request: POST https://api.telegram.org/bot7388192040:AAE6ySUHROsj21UOZkSxs4uOmdVnRrKTmC4/getUpdates "HTTP/1.1 200 OK"
2024-10-22 23:11:14,984 - httpx - INFO - HTTP Request: POST https://api.telegram.org/bot7388192040:AAE6ySUHROsj21UOZkSxs4uOmdVnRrKTmC4/getUpdates "HTTP/1.1 200 OK"
2024-10-22 23:11:25,715 - httpx - INFO - HTTP Request: POST https://api.telegram.org/bot7388192040:AAE6ySUHROsj21UOZkSxs4uOmdVnRrKTmC4/getUpdates "HTTP/1.1 200 OK"
2024-10-22 23:11:36,572 - httpx - INFO - HTTP Request: POST https://api.telegram.org/bot7388192040:AAE6ySUHROsj21UOZkSxs4uOmdVnRrKTmC4/getUpdates "HTTP/1.1 200 OK"
2024-10-22 23:11:46,817 - httpx - INFO - HTTP Request: POST https://api.telegram.org/bot7388192040:AAE6ySUHROsj21UOZkSxs4uOmdVnRrKTmC4/getUpdates "HTTP/1.1 200 OK"
2024-10-22 23:11:57,266 - httpx - INFO - HTTP Request: POST https://api.telegram.org/bot7388192040:AAE6ySUHROsj21UOZkSxs4uOmdVnRrKTmC4/getUpdates "HTTP/1.1 200 OK"
2024-10-22 23:12:07,393 - httpx - INFO - HTTP Request: POST https://api.telegram.org/bot7388192040:AAE6ySUHROsj21UOZkSxs4uOmdVnRrKTmC4/getUpdates "HTTP/1.1 200 OK"
2024-10-22 23:12:17,531 - httpx - INFO - HTTP Request: POST https://api.telegram.org/bot7388192040:AAE6ySUHROsj21UOZkSxs4uOmdVnRrKTmC4/getUpdates "HTTP/1.1 200 OK"
2024-10-22 23:12:28,345 - httpx - INFO - HTTP Request: POST https://api.telegram.org/bot7388192040:AAE6ySUHROsj21UOZkSxs4uOmdVnRrKTmC4/getUpdates "HTTP/1.1 200 OK"
2024-10-22 23:12:38,625 - httpx - INFO - HTTP Request: POST https://api.telegram.org/bot7388192040:AAE6ySUHROsj21UOZkSxs4uOmdVnRrKTmC4/getUpdates "HTTP/1.1 200 OK"
2024-10-22 23:12:48,762 - httpx - INFO - HTTP Request: POST https://api.telegram.org/bot7388192040:AAE6ySUHROsj21UOZkSxs4uOmdVnRrKTmC4/getUpdates "HTTP/1.1 200 OK"
2024-10-22 23:12:59,018 - httpx - INFO - HTTP Request: POST https://api.telegram.org/bot7388192040:AAE6ySUHROsj21UOZkSxs4uOmdVnRrKTmC4/getUpdates "HTTP/1.1 200 OK"
2024-10-22 23:13:09,105 - httpx - INFO - HTTP Request: POST https://api.telegram.org/bot7388192040:AAE6ySUHROsj21UOZkSxs4uOmdVnRrKTmC4/getUpdates "HTTP/1.1 200 OK"
2024-10-22 23:13:19,379 - httpx - INFO - HTTP Request: POST https://api.telegram.org/bot7388192040:AAE6ySUHROsj21UOZkSxs4uOmdVnRrKTmC4/getUpdates "HTTP/1.1 200 OK"
2024-10-22 23:13:29,721 - httpx - INFO - HTTP Request: POST https://api.telegram.org/bot7388192040:AAE6ySUHROsj21UOZkSxs4uOmdVnRrKTmC4/getUpdates "HTTP/1.1 200 OK"
2024-10-22 23:13:41,293 - httpx - INFO - HTTP Request: POST https://api.telegram.org/bot7388192040:AAE6ySUHROsj21UOZkSxs4uOmdVnRrKTmC4/getUpdates "HTTP/1.1 200 OK"
2024-10-22 23:13:51,421 - httpx - INFO - HTTP Request: POST https://api.telegram.org/bot7388192040:AAE6ySUHROsj21UOZkSxs4uOmdVnRrKTmC4/getUpdates "HTTP/1.1 200 OK"
2024-10-22 23:14:01,536 - httpx - INFO - HTTP Request: POST https://api.telegram.org/bot7388192040:AAE6ySUHROsj21UOZkSxs4uOmdVnRrKTmC4/getUpdates "HTTP/1.1 200 OK"
2024-10-22 23:14:11,694 - httpx - INFO - HTTP Request: POST https://api.telegram.org/bot7388192040:AAE6ySUHROsj21UOZkSxs4uOmdVnRrKTmC4/getUpdates "HTTP/1.1 200 OK"
2024-10-22 23:14:21,830 - httpx - INFO - HTTP Request: POST https://api.telegram.org/bot7388192040:AAE6ySUHROsj21UOZkSxs4uOmdVnRrKTmC4/getUpdates "HTTP/1.1 200 OK"
2024-10-22 23:14:32,082 - httpx - INFO - HTTP Request: POST https://api.telegram.org/bot7388192040:AAE6ySUHROsj21UOZkSxs4uOmdVnRrKTmC4/getUpdates "HTTP/1.1 200 OK"
2024-10-22 23:14:42,317 - httpx - INFO - HTTP Request: POST https://api.telegram.org/bot7388192040:AAE6ySUHROsj21UOZkSxs4uOmdVnRrKTmC4/getUpdates "HTTP/1.1 200 OK"
2024-10-22 23:14:52,460 - httpx - INFO - HTTP Request: POST https://api.telegram.org/bot7388192040:AAE6ySUHROsj21UOZkSxs4uOmdVnRrKTmC4/getUpdates "HTTP/1.1 200 OK"
2024-10-22 23:15:02,689 - httpx - INFO - HTTP Request: POST https://api.telegram.org/bot7388192040:AAE6ySUHROsj21UOZkSxs4uOmdVnRrKTmC4/getUpdates "HTTP/1.1 200 OK"
2024-10-22 23:15:12,830 - httpx - INFO - HTTP Request: POST https://api.telegram.org/bot7388192040:AAE6ySUHROsj21UOZkSxs4uOmdVnRrKTmC4/getUpdates "HTTP/1.1 200 OK"
2024-10-22 23:15:22,976 - httpx - INFO - HTTP Request: POST https://api.telegram.org/bot7388192040:AAE6ySUHROsj21UOZkSxs4uOmdVnRrKTmC4/getUpdates "HTTP/1.1 200 OK"
2024-10-22 23:15:33,319 - httpx - INFO - HTTP Request: POST https://api.telegram.org/bot7388192040:AAE6ySUHROsj21UOZkSxs4uOmdVnRrKTmC4/getUpdates "HTTP/1.1 200 OK"
2024-10-22 23:15:43,451 - httpx - INFO - HTTP Request: POST https://api.telegram.org/bot7388192040:AAE6ySUHROsj21UOZkSxs4uOmdVnRrKTmC4/getUpdates "HTTP/1.1 200 OK"
2024-10-22 23:15:53,589 - httpx - INFO - HTTP Request: POST https://api.telegram.org/bot7388192040:AAE6ySUHROsj21UOZkSxs4uOmdVnRrKTmC4/getUpdates "HTTP/1.1 200 OK"
2024-10-22 23:16:03,722 - httpx - INFO - HTTP Request: POST https://api.telegram.org/bot7388192040:AAE6ySUHROsj21UOZkSxs4uOmdVnRrKTmC4/getUpdates "HTTP/1.1 200 OK"
2024-10-22 23:16:13,885 - httpx - INFO - HTTP Request: POST https://api.telegram.org/bot7388192040:AAE6ySUHROsj21UOZkSxs4uOmdVnRrKTmC4/getUpdates "HTTP/1.1 200 OK"
2024-10-22 23:16:24,007 - httpx - INFO - HTTP Request: POST https://api.telegram.org/bot7388192040:AAE6ySUHROsj21UOZkSxs4uOmdVnRrKTmC4/getUpdates "HTTP/1.1 200 OK"
2024-10-22 23:16:34,227 - httpx - INFO - HTTP Request: POST https://api.telegram.org/bot7388192040:AAE6ySUHROsj21UOZkSxs4uOmdVnRrKTmC4/getUpdates "HTTP/1.1 200 OK"
2024-10-22 23:16:44,383 - httpx - INFO - HTTP Request: POST https://api.telegram.org/bot7388192040:AAE6ySUHROsj21UOZkSxs4uOmdVnRrKTmC4/getUpdates "HTTP/1.1 200 OK"
2024-10-22 23:16:54,623 - httpx - INFO - HTTP Request: POST https://api.telegram.org/bot7388192040:AAE6ySUHROsj21UOZkSxs4uOmdVnRrKTmC4/getUpdates "HTTP/1.1 200 OK"
2024-10-22 23:17:05,128 - httpx - INFO - HTTP Request: POST https://api.telegram.org/bot7388192040:AAE6ySUHROsj21UOZkSxs4uOmdVnRrKTmC4/getUpdates "HTTP/1.1 200 OK"
2024-10-22 23:17:15,406 - httpx - INFO - HTTP Request: POST https://api.telegram.org/bot7388192040:AAE6ySUHROsj21UOZkSxs4uOmdVnRrKTmC4/getUpdates "HTTP/1.1 200 OK"
2024-10-22 23:17:25,654 - httpx - INFO - HTTP Request: POST https://api.telegram.org/bot7388192040:AAE6ySUHROsj21UOZkSxs4uOmdVnRrKTmC4/getUpdates "HTTP/1.1 200 OK"
2024-10-22 23:17:35,808 - httpx - INFO - HTTP Request: POST https://api.telegram.org/bot7388192040:AAE6ySUHROsj21UOZkSxs4uOmdVnRrKTmC4/getUpdates "HTTP/1.1 200 OK"
2024-10-22 23:17:45,932 - httpx - INFO - HTTP Request: POST https://api.telegram.org/bot7388192040:AAE6ySUHROsj21UOZkSxs4uOmdVnRrKTmC4/getUpdates "HTTP/1.1 200 OK"
2024-10-22 23:17:56,267 - httpx - INFO - HTTP Request: POST https://api.telegram.org/bot7388192040:AAE6ySUHROsj21UOZkSxs4uOmdVnRrKTmC4/getUpdates "HTTP/1.1 200 OK"
2024-10-22 23:18:06,410 - httpx - INFO - HTTP Request: POST https://api.telegram.org/bot7388192040:AAE6ySUHROsj21UOZkSxs4uOmdVnRrKTmC4/getUpdates "HTTP/1.1 200 OK"
2024-10-22 23:18:16,502 - httpx - INFO - HTTP Request: POST https://api.telegram.org/bot7388192040:AAE6ySUHROsj21UOZkSxs4uOmdVnRrKTmC4/getUpdates "HTTP/1.1 200 OK"
2024-10-22 23:18:26,757 - httpx - INFO - HTTP Request: POST https://api.telegram.org/bot7388192040:AAE6ySUHROsj21UOZkSxs4uOmdVnRrKTmC4/getUpdates "HTTP/1.1 200 OK"
2024-10-22 23:18:36,921 - httpx - INFO - HTTP Request: POST https://api.telegram.org/bot7388192040:AAE6ySUHROsj21UOZkSxs4uOmdVnRrKTmC4/getUpdates "HTTP/1.1 200 OK"
2024-10-22 23:18:47,205 - httpx - INFO - HTTP Request: POST https://api.telegram.org/bot7388192040:AAE6ySUHROsj21UOZkSxs4uOmdVnRrKTmC4/getUpdates "HTTP/1.1 200 OK"
2024-10-22 23:18:57,295 - httpx - INFO - HTTP Request: POST https://api.telegram.org/bot7388192040:AAE6ySUHROsj21UOZkSxs4uOmdVnRrKTmC4/getUpdates "HTTP/1.1 200 OK"
2024-10-22 23:19:07,435 - httpx - INFO - HTTP Request: POST https://api.telegram.org/bot7388192040:AAE6ySUHROsj21UOZkSxs4uOmdVnRrKTmC4/getUpdates "HTTP/1.1 200 OK"
2024-10-22 23:19:17,590 - httpx - INFO - HTTP Request: POST https://api.telegram.org/bot7388192040:AAE6ySUHROsj21UOZkSxs4uOmdVnRrKTmC4/getUpdates "HTTP/1.1 200 OK"
2024-10-22 23:19:28,737 - httpx - INFO - HTTP Request: POST https://api.telegram.org/bot7388192040:AAE6ySUHROsj21UOZkSxs4uOmdVnRrKTmC4/getUpdates "HTTP/1.1 200 OK"
2024-10-22 23:19:39,602 - httpx - INFO - HTTP Request: POST https://api.telegram.org/bot7388192040:AAE6ySUHROsj21UOZkSxs4uOmdVnRrKTmC4/getUpdates "HTTP/1.1 200 OK"
2024-10-22 23:19:50,673 - __main__ - INFO - Fernet успішно ініціалізовано
2024-10-22 23:19:50,673 - __main__ - INFO - База даних успішно ініціалізована
2024-10-22 23:19:50,673 - __main__ - INFO - Starting the bot
2024-10-22 23:19:51,197 - __main__ - INFO - Handlers added, starting polling
2024-10-22 23:19:51,880 - httpx - INFO - HTTP Request: POST https://api.telegram.org/bot7388192040:AAE6ySUHROsj21UOZkSxs4uOmdVnRrKTmC4/getMe "HTTP/1.1 200 OK"
2024-10-22 23:19:52,080 - httpx - INFO - HTTP Request: POST https://api.telegram.org/bot7388192040:AAE6ySUHROsj21UOZkSxs4uOmdVnRrKTmC4/deleteWebhook "HTTP/1.1 200 OK"
2024-10-22 23:19:52,080 - telegram.ext.Application - INFO - Application started
2024-10-22 23:19:52,789 - httpx - INFO - HTTP Request: POST https://api.telegram.org/bot7388192040:AAE6ySUHROsj21UOZkSxs4uOmdVnRrKTmC4/getUpdates "HTTP/1.1 200 OK"
2024-10-22 23:19:52,796 - __main__ - INFO - Отримано натискання кнопки від користувача 659171286: Отримати зашифрований ключ
2024-10-22 23:19:52,796 - __main__ - INFO - Знайдено дані гаманця для користувача 659171286
2024-10-22 23:19:52,796 - __main__ - INFO - Відправляємо зашифрований ключ користувачу 659171286
2024-10-22 23:19:53,322 - httpx - INFO - HTTP Request: POST https://api.telegram.org/bot7388192040:AAE6ySUHROsj21UOZkSxs4uOmdVnRrKTmC4/sendMessage "HTTP/1.1 200 OK"
2024-10-22 23:19:53,322 - __main__ - INFO - Відповідь успішно надіслано користувачу 659171286
2024-10-22 23:19:53,322 - __main__ - INFO - Отримано натискання кнопки від користувача 659171286: Отримати розшифрований ключ
2024-10-22 23:19:53,322 - __main__ - INFO - Знайдено дані гаманця для користувача 659171286
2024-10-22 23:19:53,322 - __main__ - INFO - Спроба розшифрування ключа для користувача 659171286
2024-10-22 23:19:53,336 - __main__ - INFO - Ключ успішно розшифровано для користувача 659171286
2024-10-22 23:19:53,623 - httpx - INFO - HTTP Request: POST https://api.telegram.org/bot7388192040:AAE6ySUHROsj21UOZkSxs4uOmdVnRrKTmC4/sendMessage "HTTP/1.1 200 OK"
2024-10-22 23:19:53,623 - __main__ - INFO - Відповідь успішно надіслано користувачу 659171286
2024-10-22 23:20:02,217 - httpx - INFO - HTTP Request: POST https://api.telegram.org/bot7388192040:AAE6ySUHROsj21UOZkSxs4uOmdVnRrKTmC4/getUpdates "HTTP/1.1 200 OK"
2024-10-22 23:20:03,560 - httpx - INFO - HTTP Request: POST https://api.telegram.org/bot7388192040:AAE6ySUHROsj21UOZkSxs4uOmdVnRrKTmC4/sendMessage "HTTP/1.1 200 OK"
2024-10-22 23:20:07,763 - httpx - INFO - HTTP Request: POST https://api.telegram.org/bot7388192040:AAE6ySUHROsj21UOZkSxs4uOmdVnRrKTmC4/getUpdates "HTTP/1.1 200 OK"
2024-10-22 23:20:07,763 - __main__ - INFO - Отримано натискання кнопки від користувача 867084500: Отримати зашифрований ключ
2024-10-22 23:20:07,778 - __main__ - INFO - Знайдено дані гаманця для користувача 867084500
2024-10-22 23:20:07,781 - __main__ - INFO - Відправляємо зашифрований ключ користувачу 867084500
2024-10-22 23:20:08,170 - httpx - INFO - HTTP Request: POST https://api.telegram.org/bot7388192040:AAE6ySUHROsj21UOZkSxs4uOmdVnRrKTmC4/sendMessage "HTTP/1.1 200 OK"
2024-10-22 23:20:08,175 - __main__ - INFO - Відповідь успішно надіслано користувачу 867084500
2024-10-22 23:20:09,698 - httpx - INFO - HTTP Request: POST https://api.telegram.org/bot7388192040:AAE6ySUHROsj21UOZkSxs4uOmdVnRrKTmC4/getUpdates "HTTP/1.1 200 OK"
2024-10-22 23:20:09,698 - __main__ - INFO - Команда /start від користувача 659171286
2024-10-22 23:20:09,698 - __main__ - INFO - Знайдено існуючий гаманець для користувача 659171286
2024-10-22 23:20:09,896 - httpx - INFO - HTTP Request: POST https://api.telegram.org/bot7388192040:AAE6ySUHROsj21UOZkSxs4uOmdVnRrKTmC4/sendMessage "HTTP/1.1 200 OK"
2024-10-22 23:20:10,128 - httpx - INFO - HTTP Request: POST https://api.telegram.org/bot7388192040:AAE6ySUHROsj21UOZkSxs4uOmdVnRrKTmC4/getUpdates "HTTP/1.1 200 OK"
2024-10-22 23:20:10,131 - __main__ - INFO - Отримано натискання кнопки від користувача 867084500: Отримати розшифрований ключ
2024-10-22 23:20:10,133 - __main__ - INFO - Знайдено дані гаманця для користувача 867084500
2024-10-22 23:20:10,133 - __main__ - INFO - Спроба розшифрування ключа для користувача 867084500
2024-10-22 23:20:10,134 - __main__ - INFO - Ключ успішно розшифровано для користувача 867084500
2024-10-22 23:20:10,309 - httpx - INFO - HTTP Request: POST https://api.telegram.org/bot7388192040:AAE6ySUHROsj21UOZkSxs4uOmdVnRrKTmC4/sendMessage "HTTP/1.1 200 OK"
2024-10-22 23:20:10,317 - __main__ - INFO - Відповідь успішно надіслано користувачу 867084500
2024-10-22 23:20:20,349 - httpx - INFO - HTTP Request: POST https://api.telegram.org/bot7388192040:AAE6ySUHROsj21UOZkSxs4uOmdVnRrKTmC4/getUpdates "HTTP/1.1 200 OK"
2024-10-22 23:20:30,689 - httpx - INFO - HTTP Request: POST https://api.telegram.org/bot7388192040:AAE6ySUHROsj21UOZkSxs4uOmdVnRrKTmC4/getUpdates "HTTP/1.1 200 OK"
2024-10-22 23:20:40,932 - httpx - INFO - HTTP Request: POST https://api.telegram.org/bot7388192040:AAE6ySUHROsj21UOZkSxs4uOmdVnRrKTmC4/getUpdates "HTTP/1.1 200 OK"
2024-10-22 23:20:51,285 - httpx - INFO - HTTP Request: POST https://api.telegram.org/bot7388192040:AAE6ySUHROsj21UOZkSxs4uOmdVnRrKTmC4/getUpdates "HTTP/1.1 200 OK"
2024-10-22 23:21:01,910 - httpx - INFO - HTTP Request: POST https://api.telegram.org/bot7388192040:AAE6ySUHROsj21UOZkSxs4uOmdVnRrKTmC4/getUpdates "HTTP/1.1 200 OK"
2024-10-22 23:21:12,162 - httpx - INFO - HTTP Request: POST https://api.telegram.org/bot7388192040:AAE6ySUHROsj21UOZkSxs4uOmdVnRrKTmC4/getUpdates "HTTP/1.1 200 OK"
2024-10-22 23:21:22,401 - httpx - INFO - HTTP Request: POST https://api.telegram.org/bot7388192040:AAE6ySUHROsj21UOZkSxs4uOmdVnRrKTmC4/getUpdates "HTTP/1.1 200 OK"
2024-10-22 23:21:32,747 - httpx - INFO - HTTP Request: POST https://api.telegram.org/bot7388192040:AAE6ySUHROsj21UOZkSxs4uOmdVnRrKTmC4/getUpdates "HTTP/1.1 200 OK"
2024-10-22 23:21:42,982 - httpx - INFO - HTTP Request: POST https://api.telegram.org/bot7388192040:AAE6ySUHROsj21UOZkSxs4uOmdVnRrKTmC4/getUpdates "HTTP/1.1 200 OK"
2024-10-22 23:21:53,688 - httpx - INFO - HTTP Request: POST https://api.telegram.org/bot7388192040:AAE6ySUHROsj21UOZkSxs4uOmdVnRrKTmC4/getUpdates "HTTP/1.1 200 OK"
2024-10-22 23:22:04,068 - httpx - INFO - HTTP Request: POST https://api.telegram.org/bot7388192040:AAE6ySUHROsj21UOZkSxs4uOmdVnRrKTmC4/getUpdates "HTTP/1.1 200 OK"
2024-10-22 23:22:14,318 - httpx - INFO - HTTP Request: POST https://api.telegram.org/bot7388192040:AAE6ySUHROsj21UOZkSxs4uOmdVnRrKTmC4/getUpdates "HTTP/1.1 200 OK"
2024-10-22 23:22:24,458 - httpx - INFO - HTTP Request: POST https://api.telegram.org/bot7388192040:AAE6ySUHROsj21UOZkSxs4uOmdVnRrKTmC4/getUpdates "HTTP/1.1 200 OK"
2024-10-22 23:22:34,645 - httpx - INFO - HTTP Request: POST https://api.telegram.org/bot7388192040:AAE6ySUHROsj21UOZkSxs4uOmdVnRrKTmC4/getUpdates "HTTP/1.1 200 OK"
2024-10-22 23:22:44,749 - httpx - INFO - HTTP Request: POST https://api.telegram.org/bot7388192040:AAE6ySUHROsj21UOZkSxs4uOmdVnRrKTmC4/getUpdates "HTTP/1.1 200 OK"
2024-10-22 23:22:55,080 - httpx - INFO - HTTP Request: POST https://api.telegram.org/bot7388192040:AAE6ySUHROsj21UOZkSxs4uOmdVnRrKTmC4/getUpdates "HTTP/1.1 200 OK"
2024-10-22 23:23:23,734 - __main__ - INFO - Fernet успішно ініціалізовано
2024-10-22 23:23:23,734 - __main__ - INFO - База даних успішно ініціалізована
2024-10-22 23:23:23,734 - __main__ - INFO - Starting the bot
2024-10-22 23:23:24,264 - __main__ - INFO - Handlers added, starting polling
2024-10-22 23:23:24,764 - httpx - INFO - HTTP Request: POST https://api.telegram.org/bot7388192040:AAE6ySUHROsj21UOZkSxs4uOmdVnRrKTmC4/getMe "HTTP/1.1 200 OK"
2024-10-22 23:23:24,888 - httpx - INFO - HTTP Request: POST https://api.telegram.org/bot7388192040:AAE6ySUHROsj21UOZkSxs4uOmdVnRrKTmC4/deleteWebhook "HTTP/1.1 200 OK"
2024-10-22 23:23:24,888 - telegram.ext.Application - INFO - Application started
2024-10-22 23:23:29,587 - httpx - INFO - HTTP Request: POST https://api.telegram.org/bot7388192040:AAE6ySUHROsj21UOZkSxs4uOmdVnRrKTmC4/getUpdates "HTTP/1.1 200 OK"
2024-10-22 23:23:29,590 - __main__ - INFO - Отримано натискання кнопки від користувача 867084500: Отримати зашифрований ключ
2024-10-22 23:23:29,593 - __main__ - INFO - Знайдено дані гаманця для користувача 867084500
2024-10-22 23:23:29,593 - __main__ - INFO - Відправляємо зашифрований ключ користувачу 867084500
2024-10-22 23:23:29,792 - httpx - INFO - HTTP Request: POST https://api.telegram.org/bot7388192040:AAE6ySUHROsj21UOZkSxs4uOmdVnRrKTmC4/sendMessage "HTTP/1.1 200 OK"
2024-10-22 23:23:29,794 - __main__ - INFO - Відповідь успішно надіслано користувачу 867084500
2024-10-22 23:23:33,453 - httpx - INFO - HTTP Request: POST https://api.telegram.org/bot7388192040:AAE6ySUHROsj21UOZkSxs4uOmdVnRrKTmC4/getUpdates "HTTP/1.1 200 OK"
2024-10-22 23:23:33,453 - __main__ - INFO - Отримано натискання кнопки від користувача 867084500: Отримати розшифрований ключ
2024-10-22 23:23:33,453 - __main__ - INFO - Знайдено дані гаманця для користувача 867084500
2024-10-22 23:23:33,453 - __main__ - INFO - Спроба розшифрування ключа для користувача 867084500
2024-10-22 23:23:33,468 - __main__ - INFO - Ключ успішно розшифровано для користувача 867084500
2024-10-22 23:23:33,780 - httpx - INFO - HTTP Request: POST https://api.telegram.org/bot7388192040:AAE6ySUHROsj21UOZkSxs4uOmdVnRrKTmC4/sendMessage "HTTP/1.1 200 OK"
2024-10-22 23:23:33,791 - __main__ - INFO - Відповідь успішно надіслано користувачу 867084500
2024-10-22 23:23:43,711 - httpx - INFO - HTTP Request: POST https://api.telegram.org/bot7388192040:AAE6ySUHROsj21UOZkSxs4uOmdVnRrKTmC4/getUpdates "HTTP/1.1 200 OK"
2024-10-22 23:23:53,881 - httpx - INFO - HTTP Request: POST https://api.telegram.org/bot7388192040:AAE6ySUHROsj21UOZkSxs4uOmdVnRrKTmC4/getUpdates "HTTP/1.1 200 OK"
2024-10-22 23:24:04,184 - httpx - INFO - HTTP Request: POST https://api.telegram.org/bot7388192040:AAE6ySUHROsj21UOZkSxs4uOmdVnRrKTmC4/getUpdates "HTTP/1.1 200 OK"
2024-10-22 23:24:14,427 - httpx - INFO - HTTP Request: POST https://api.telegram.org/bot7388192040:AAE6ySUHROsj21UOZkSxs4uOmdVnRrKTmC4/getUpdates "HTTP/1.1 200 OK"
2024-10-22 23:24:24,579 - httpx - INFO - HTTP Request: POST https://api.telegram.org/bot7388192040:AAE6ySUHROsj21UOZkSxs4uOmdVnRrKTmC4/getUpdates "HTTP/1.1 200 OK"
2024-10-22 23:24:34,907 - httpx - INFO - HTTP Request: POST https://api.telegram.org/bot7388192040:AAE6ySUHROsj21UOZkSxs4uOmdVnRrKTmC4/getUpdates "HTTP/1.1 200 OK"
2024-10-22 23:24:45,150 - httpx - INFO - HTTP Request: POST https://api.telegram.org/bot7388192040:AAE6ySUHROsj21UOZkSxs4uOmdVnRrKTmC4/getUpdates "HTTP/1.1 200 OK"
2024-10-22 23:24:55,401 - httpx - INFO - HTTP Request: POST https://api.telegram.org/bot7388192040:AAE6ySUHROsj21UOZkSxs4uOmdVnRrKTmC4/getUpdates "HTTP/1.1 200 OK"
2024-10-22 23:25:05,626 - httpx - INFO - HTTP Request: POST https://api.telegram.org/bot7388192040:AAE6ySUHROsj21UOZkSxs4uOmdVnRrKTmC4/getUpdates "HTTP/1.1 200 OK"
2024-10-22 23:25:15,782 - httpx - INFO - HTTP Request: POST https://api.telegram.org/bot7388192040:AAE6ySUHROsj21UOZkSxs4uOmdVnRrKTmC4/getUpdates "HTTP/1.1 200 OK"
2024-10-22 23:25:21,090 - httpx - INFO - HTTP Request: POST https://api.telegram.org/bot7388192040:AAE6ySUHROsj21UOZkSxs4uOmdVnRrKTmC4/getUpdates "HTTP/1.1 200 OK"
2024-10-22 23:25:21,090 - __main__ - INFO - Отримано натискання кнопки від користувача 659171286: Отримати зашифрований ключ
2024-10-22 23:25:21,106 - __main__ - INFO - Знайдено дані гаманця для користувача 659171286
2024-10-22 23:25:21,106 - __main__ - INFO - Відправляємо зашифрований ключ користувачу 659171286
2024-10-22 23:25:21,203 - httpx - INFO - HTTP Request: POST https://api.telegram.org/bot7388192040:AAE6ySUHROsj21UOZkSxs4uOmdVnRrKTmC4/getUpdates "HTTP/1.1 200 OK"
2024-10-22 23:25:21,607 - httpx - INFO - HTTP Request: POST https://api.telegram.org/bot7388192040:AAE6ySUHROsj21UOZkSxs4uOmdVnRrKTmC4/sendMessage "HTTP/1.1 200 OK"
2024-10-22 23:25:21,618 - __main__ - INFO - Відповідь успішно надіслано користувачу 659171286
2024-10-22 23:25:21,618 - __main__ - INFO - Отримано натискання кнопки від користувача 659171286: Отримати розшифрований ключ
2024-10-22 23:25:21,621 - __main__ - INFO - Знайдено дані гаманця для користувача 659171286
2024-10-22 23:25:21,621 - __main__ - INFO - Спроба розшифрування ключа для користувача 659171286
2024-10-22 23:25:21,621 - __main__ - INFO - Ключ успішно розшифровано для користувача 659171286
2024-10-22 23:25:21,920 - httpx - INFO - HTTP Request: POST https://api.telegram.org/bot7388192040:AAE6ySUHROsj21UOZkSxs4uOmdVnRrKTmC4/sendMessage "HTTP/1.1 200 OK"
2024-10-22 23:25:21,920 - __main__ - INFO - Відповідь успішно надіслано користувачу 659171286
2024-10-22 23:25:31,339 - httpx - INFO - HTTP Request: POST https://api.telegram.org/bot7388192040:AAE6ySUHROsj21UOZkSxs4uOmdVnRrKTmC4/getUpdates "HTTP/1.1 200 OK"
2024-10-22 23:25:41,476 - httpx - INFO - HTTP Request: POST https://api.telegram.org/bot7388192040:AAE6ySUHROsj21UOZkSxs4uOmdVnRrKTmC4/getUpdates "HTTP/1.1 200 OK"
2024-10-22 23:25:51,716 - httpx - INFO - HTTP Request: POST https://api.telegram.org/bot7388192040:AAE6ySUHROsj21UOZkSxs4uOmdVnRrKTmC4/getUpdates "HTTP/1.1 200 OK"
2024-10-22 23:26:01,859 - httpx - INFO - HTTP Request: POST https://api.telegram.org/bot7388192040:AAE6ySUHROsj21UOZkSxs4uOmdVnRrKTmC4/getUpdates "HTTP/1.1 200 OK"
2024-10-22 23:26:13,437 - httpx - INFO - HTTP Request: POST https://api.telegram.org/bot7388192040:AAE6ySUHROsj21UOZkSxs4uOmdVnRrKTmC4/getUpdates "HTTP/1.1 200 OK"
2024-10-22 23:26:23,550 - httpx - INFO - HTTP Request: POST https://api.telegram.org/bot7388192040:AAE6ySUHROsj21UOZkSxs4uOmdVnRrKTmC4/getUpdates "HTTP/1.1 200 OK"
2024-10-22 23:26:34,215 - httpx - INFO - HTTP Request: POST https://api.telegram.org/bot7388192040:AAE6ySUHROsj21UOZkSxs4uOmdVnRrKTmC4/getUpdates "HTTP/1.1 200 OK"
2024-10-22 23:26:44,458 - httpx - INFO - HTTP Request: POST https://api.telegram.org/bot7388192040:AAE6ySUHROsj21UOZkSxs4uOmdVnRrKTmC4/getUpdates "HTTP/1.1 200 OK"
2024-10-22 23:26:55,924 - httpx - INFO - HTTP Request: POST https://api.telegram.org/bot7388192040:AAE6ySUHROsj21UOZkSxs4uOmdVnRrKTmC4/getUpdates "HTTP/1.1 200 OK"
2024-10-22 23:27:07,087 - httpx - INFO - HTTP Request: POST https://api.telegram.org/bot7388192040:AAE6ySUHROsj21UOZkSxs4uOmdVnRrKTmC4/getUpdates "HTTP/1.1 200 OK"
2024-10-22 23:27:17,630 - httpx - INFO - HTTP Request: POST https://api.telegram.org/bot7388192040:AAE6ySUHROsj21UOZkSxs4uOmdVnRrKTmC4/getUpdates "HTTP/1.1 200 OK"
2024-10-22 23:27:28,384 - httpx - INFO - HTTP Request: POST https://api.telegram.org/bot7388192040:AAE6ySUHROsj21UOZkSxs4uOmdVnRrKTmC4/getUpdates "HTTP/1.1 200 OK"
2024-10-22 23:27:38,822 - httpx - INFO - HTTP Request: POST https://api.telegram.org/bot7388192040:AAE6ySUHROsj21UOZkSxs4uOmdVnRrKTmC4/getUpdates "HTTP/1.1 200 OK"
2024-10-22 23:27:49,075 - httpx - INFO - HTTP Request: POST https://api.telegram.org/bot7388192040:AAE6ySUHROsj21UOZkSxs4uOmdVnRrKTmC4/getUpdates "HTTP/1.1 200 OK"
2024-10-22 23:28:00,021 - httpx - INFO - HTTP Request: POST https://api.telegram.org/bot7388192040:AAE6ySUHROsj21UOZkSxs4uOmdVnRrKTmC4/getUpdates "HTTP/1.1 200 OK"
2024-10-22 23:28:10,472 - httpx - INFO - HTTP Request: POST https://api.telegram.org/bot7388192040:AAE6ySUHROsj21UOZkSxs4uOmdVnRrKTmC4/getUpdates "HTTP/1.1 200 OK"
2024-10-22 23:28:21,496 - httpx - INFO - HTTP Request: POST https://api.telegram.org/bot7388192040:AAE6ySUHROsj21UOZkSxs4uOmdVnRrKTmC4/getUpdates "HTTP/1.1 200 OK"
2024-10-22 23:28:32,447 - httpx - INFO - HTTP Request: POST https://api.telegram.org/bot7388192040:AAE6ySUHROsj21UOZkSxs4uOmdVnRrKTmC4/getUpdates "HTTP/1.1 200 OK"
2024-10-22 23:28:43,239 - httpx - INFO - HTTP Request: POST https://api.telegram.org/bot7388192040:AAE6ySUHROsj21UOZkSxs4uOmdVnRrKTmC4/getUpdates "HTTP/1.1 200 OK"
2024-10-22 23:28:53,577 - httpx - INFO - HTTP Request: POST https://api.telegram.org/bot7388192040:AAE6ySUHROsj21UOZkSxs4uOmdVnRrKTmC4/getUpdates "HTTP/1.1 200 OK"
2024-10-22 23:29:18,511 - __main__ - INFO - Fernet успішно ініціалізовано
2024-10-22 23:29:18,511 - __main__ - INFO - База даних успішно ініціалізована
2024-10-22 23:29:18,511 - __main__ - INFO - Starting the bot
2024-10-22 23:29:19,008 - __main__ - INFO - Handlers added, starting polling
2024-10-22 23:29:22,849 - httpx - INFO - HTTP Request: POST https://api.telegram.org/bot7388192040:AAE6ySUHROsj21UOZkSxs4uOmdVnRrKTmC4/getMe "HTTP/1.1 200 OK"
2024-10-22 23:29:23,639 - httpx - INFO - HTTP Request: POST https://api.telegram.org/bot7388192040:AAE6ySUHROsj21UOZkSxs4uOmdVnRrKTmC4/deleteWebhook "HTTP/1.1 200 OK"
2024-10-22 23:29:23,639 - telegram.ext.Application - INFO - Application started
2024-10-22 23:29:32,074 - httpx - INFO - HTTP Request: POST https://api.telegram.org/bot7388192040:AAE6ySUHROsj21UOZkSxs4uOmdVnRrKTmC4/getUpdates "HTTP/1.1 200 OK"
2024-10-22 23:29:32,089 - __main__ - INFO - Команда /start від користувача 7432517734
2024-10-22 23:29:32,089 - __main__ - INFO - Створення нового гаманця для користувача 7432517734
2024-10-22 23:29:32,121 - __main__ - INFO - Новий гаманець успішно створено для користувача 7432517734
2024-10-22 23:29:33,332 - httpx - INFO - HTTP Request: POST https://api.telegram.org/bot7388192040:AAE6ySUHROsj21UOZkSxs4uOmdVnRrKTmC4/sendMessage "HTTP/1.1 200 OK"
2024-10-22 23:29:35,360 - httpx - INFO - HTTP Request: POST https://api.telegram.org/bot7388192040:AAE6ySUHROsj21UOZkSxs4uOmdVnRrKTmC4/sendMessage "HTTP/1.1 200 OK"
2024-10-22 23:29:42,528 - httpx - INFO - HTTP Request: POST https://api.telegram.org/bot7388192040:AAE6ySUHROsj21UOZkSxs4uOmdVnRrKTmC4/getUpdates "HTTP/1.1 200 OK"
2024-10-22 23:29:44,160 - httpx - INFO - HTTP Request: POST https://api.telegram.org/bot7388192040:AAE6ySUHROsj21UOZkSxs4uOmdVnRrKTmC4/getUpdates "HTTP/1.1 200 OK"
2024-10-22 23:29:44,160 - __main__ - INFO - Отримано натискання кнопки від користувача 7432517734: Отримати зашифрований ключ
2024-10-22 23:29:44,175 - __main__ - INFO - Знайдено дані гаманця для користувача 7432517734
2024-10-22 23:29:44,177 - __main__ - INFO - Відправляємо зашифрований ключ користувачу 7432517734
2024-10-22 23:29:45,390 - httpx - INFO - HTTP Request: POST https://api.telegram.org/bot7388192040:AAE6ySUHROsj21UOZkSxs4uOmdVnRrKTmC4/sendMessage "HTTP/1.1 200 OK"
2024-10-22 23:29:45,390 - __main__ - INFO - Відповідь успішно надіслано користувачу 7432517734
2024-10-22 23:29:47,852 - httpx - INFO - HTTP Request: POST https://api.telegram.org/bot7388192040:AAE6ySUHROsj21UOZkSxs4uOmdVnRrKTmC4/getUpdates "HTTP/1.1 200 OK"
2024-10-22 23:29:47,852 - __main__ - INFO - Отримано натискання кнопки від користувача 7432517734: Отримати розшифрований ключ
2024-10-22 23:29:47,852 - __main__ - INFO - Знайдено дані гаманця для користувача 7432517734
2024-10-22 23:29:47,852 - __main__ - INFO - Спроба розшифрування ключа для користувача 7432517734
2024-10-22 23:29:47,852 - __main__ - INFO - Ключ успішно розшифровано для користувача 7432517734
2024-10-22 23:29:48,471 - httpx - INFO - HTTP Request: POST https://api.telegram.org/bot7388192040:AAE6ySUHROsj21UOZkSxs4uOmdVnRrKTmC4/sendMessage "HTTP/1.1 200 OK"
2024-10-22 23:29:48,471 - __main__ - INFO - Відповідь успішно надіслано користувачу 7432517734
2024-10-22 23:29:58,292 - httpx - INFO - HTTP Request: POST https://api.telegram.org/bot7388192040:AAE6ySUHROsj21UOZkSxs4uOmdVnRrKTmC4/getUpdates "HTTP/1.1 200 OK"
2024-10-22 23:30:09,155 - httpx - INFO - HTTP Request: POST https://api.telegram.org/bot7388192040:AAE6ySUHROsj21UOZkSxs4uOmdVnRrKTmC4/getUpdates "HTTP/1.1 200 OK"
2024-10-22 23:30:20,043 - httpx - INFO - HTTP Request: POST https://api.telegram.org/bot7388192040:AAE6ySUHROsj21UOZkSxs4uOmdVnRrKTmC4/getUpdates "HTTP/1.1 200 OK"
2024-10-22 23:30:30,658 - httpx - INFO - HTTP Request: POST https://api.telegram.org/bot7388192040:AAE6ySUHROsj21UOZkSxs4uOmdVnRrKTmC4/getUpdates "HTTP/1.1 200 OK"
2024-10-22 23:30:41,208 - httpx - INFO - HTTP Request: POST https://api.telegram.org/bot7388192040:AAE6ySUHROsj21UOZkSxs4uOmdVnRrKTmC4/getUpdates "HTTP/1.1 200 OK"
2024-10-22 23:30:52,053 - httpx - INFO - HTTP Request: POST https://api.telegram.org/bot7388192040:AAE6ySUHROsj21UOZkSxs4uOmdVnRrKTmC4/getUpdates "HTTP/1.1 200 OK"
2024-10-22 23:31:03,109 - httpx - INFO - HTTP Request: POST https://api.telegram.org/bot7388192040:AAE6ySUHROsj21UOZkSxs4uOmdVnRrKTmC4/getUpdates "HTTP/1.1 200 OK"
2024-10-22 23:31:15,503 - httpx - INFO - HTTP Request: POST https://api.telegram.org/bot7388192040:AAE6ySUHROsj21UOZkSxs4uOmdVnRrKTmC4/getUpdates "HTTP/1.1 200 OK"
2024-10-22 23:31:26,356 - httpx - INFO - HTTP Request: POST https://api.telegram.org/bot7388192040:AAE6ySUHROsj21UOZkSxs4uOmdVnRrKTmC4/getUpdates "HTTP/1.1 200 OK"
2024-10-22 23:31:36,809 - httpx - INFO - HTTP Request: POST https://api.telegram.org/bot7388192040:AAE6ySUHROsj21UOZkSxs4uOmdVnRrKTmC4/getUpdates "HTTP/1.1 200 OK"
2024-10-22 23:31:48,677 - httpx - INFO - HTTP Request: POST https://api.telegram.org/bot7388192040:AAE6ySUHROsj21UOZkSxs4uOmdVnRrKTmC4/getUpdates "HTTP/1.1 200 OK"
2024-10-22 23:32:00,973 - httpx - INFO - HTTP Request: POST https://api.telegram.org/bot7388192040:AAE6ySUHROsj21UOZkSxs4uOmdVnRrKTmC4/getUpdates "HTTP/1.1 200 OK"
2024-10-22 23:32:11,522 - httpx - INFO - HTTP Request: POST https://api.telegram.org/bot7388192040:AAE6ySUHROsj21UOZkSxs4uOmdVnRrKTmC4/getUpdates "HTTP/1.1 200 OK"
2024-10-22 23:32:21,964 - httpx - INFO - HTTP Request: POST https://api.telegram.org/bot7388192040:AAE6ySUHROsj21UOZkSxs4uOmdVnRrKTmC4/getUpdates "HTTP/1.1 200 OK"
2024-10-22 23:32:32,812 - httpx - INFO - HTTP Request: POST https://api.telegram.org/bot7388192040:AAE6ySUHROsj21UOZkSxs4uOmdVnRrKTmC4/getUpdates "HTTP/1.1 200 OK"
2024-10-22 23:32:43,774 - httpx - INFO - HTTP Request: POST https://api.telegram.org/bot7388192040:AAE6ySUHROsj21UOZkSxs4uOmdVnRrKTmC4/getUpdates "HTTP/1.1 200 OK"
2024-10-22 23:32:54,638 - httpx - INFO - HTTP Request: POST https://api.telegram.org/bot7388192040:AAE6ySUHROsj21UOZkSxs4uOmdVnRrKTmC4/getUpdates "HTTP/1.1 200 OK"
2024-10-22 23:33:05,695 - httpx - INFO - HTTP Request: POST https://api.telegram.org/bot7388192040:AAE6ySUHROsj21UOZkSxs4uOmdVnRrKTmC4/getUpdates "HTTP/1.1 200 OK"
